Workbook

Sheet Final data to check
A1: Name | B1: Total Payout | C1: =SUM(_xlfn.ANCHORARRAY(B2)) -> #REF!
A2: {=TRANSPOSE('Final payout'!C1:EH1)} -> Aanya | B2: {=TRANSPOSE('Final payout'!#REF!)} -> #REF!
A3: Ahila Sundaresan
A4: Alekhya Pokuri
A5: Ambar Romero
A6: Amel Yousfi
A7: Amrita Singh
A8: Andrea Lorenzano
A9: Angayarkanni Kannan
A10: Angel Edwards
A11: Anitaben Patel
A12: Anjali Devunuri
A13: Anjana Vijayan
A14: Ankana Biswas Dutta
... A137: Rutuja Rajput

Sheet Final payout
A1: Process | B1: Description | C1: Aanya | D1: Ahila Sundaresan | E1: Alekhya Pokuri | F1: Ambar Romero | G1: Amel Yousfi | H1: Amrita Singh | I1: Andrea Lorenzano | J1: Angayarkanni Kannan | K1: Angel Edwards | L1: Anitaben Patel | M1: Anjali Devunuri | N1: Anjana Vijayan | O1: Ankana Biswas Dutta | P1: Anshu Dubey | Q1: Anusha Cheerla | R1: Anusha Kulageri | S1: Anusha Prasannakumar | T1: Arcelia Finkelberg | U1: Atchaya Rangasamy Venugopal | V1: Azumi Van Scyoc | W1: Babitha Koraganti | X1: Balasubramani Kandasamy | Y1: Cecilia Hendricks | Z1: Chandana Bathina | AA1: Chandini Yellamilli | AB1: Chinmaya Jyothi Pulikallu | AC1: Damion Newell | AD1: Deepika Chintaluri | AE1: Devi Prakash | AF1: Devicharitha Malapati | AG1: Dhanalakshmi Nelluri | AH1: Dhivya Shankar | AI1: Dhivyalakshmi Vigneshwaran | AJ1: Diksha Vijaykumar More | AK1: Divya Babu | AL1: Divya Manjeshwar kamath | AM1: Divya Shree | AN1: Erianna Lockhart | AO1: Faith Ujjwala Singh | AP1: Fallyan Redd | AQ1: Farheen Hasham | AR1: Farzana Shaik | AS1: Fnu Supriya | AT1: Foua Yang | AU1: Franklin C Onyedili | AV1: Gayatri Paramsivam | AW1: Geetalakshmi Govinthara Annadhurai | AX1: Gia Erica Coleman | AY1: Hadjer Ikram Yousfi | AZ1: Haley VanNamee | BA1: Harathi Nuvuru | BB1: Hetal Shah | BC1: I-Asia Newkirk | BD1: Infanta Clara Victor Anthony | BE1: Jaya Singh | BF1: Jayashree Swain | BG1: Jhou Yang | BH1: Jyothi Venkatasubramanya | BI1: Kabila Sivasankar | BJ1: Kavya Krishnappa | BK1: Kawanna Brown | BL1: Komala Renuka Prasad | BM1: Krishnaveni | BN1: Krithika Balasubramaniam | BO1: Lakshmi Neelima Duddula | BP1: LaSere Reid Smith | BQ1: LATHA BUSIREDDY | BR1: Latrice Adams | BS1: Lavanya Vigrahala | BT1: Laxmi Sirisha Penumecha | BU1: Lipsa Padhy | BV1: Lokeswari Gummadi | BW1: Madhana Sundari Vijayarajan | BX1: Madhavi Balineni | BY1: Madhura Alva | BZ1: Madhuri Padala | CA1: Maira Becham | CB1: Manda Talwekar | CC1: Manjunath JagadishPai | CD1: Mariko Huskey | CE1: Marilyn Brown | CF1: Marina Ibrahim | CG1: Mathangi Radhakrishnan | CH1: Michelle Cox | CI1: Minakshi Deepak | CJ1: Mojisha Mohandas | CK1: Monalisa Roy | CL1: Mool Chand | CM1: Naagarashikaa Vijayakumar | CN1: Naganandhini Ganapathimaran | CO1: Namita Mishra | CP1: Namrata Sharma | CQ1: Namratha Koratala | CR1: Narmadhadevi Dharmapalan | CS1: Neena Mathew Saravanakumar | CT1: Neha Aaggarwal | CU1: Nilopher Lopes | CV1: Nitha Chathoth Kunhikrishnan | CW1: Padmapriya krishnamoorthy | CX1: Palak Porwal | CY1: Pavithra Balaji | CZ1: Pavithra Manas Panda | DA1: Pavitra Rani Allam | DB1: Pooja Solanki | DC1: Poongothai Duraisamy | DD1: Pragyan Paramita Mohanty | DE1: Pranusha Dontineni | DF1: Prasana Kotagiri | DG1: Prathima Krishnamurthy Yadav | DH1: Prathima Lakkireddy | DI1: PRAVALLIKA NUTHALAPATI | DJ1: Priti Suman | DK1: Priyadarsini Baral | DL1: Priyanka Chandrikapure | DM1: Priyanka Dey Sarkar | DN1: Priyanka Gadar | DO1: Pushpaja Vullamgunta | DP1: Rajameenakshi Sankarasubramanian | DQ1: Rajeshwari Thammineni | DR1: Ramsheena Nadathalakkel | DS1: Ramya Muralidharan | DT1: Ramya Sudarshan Palavalli | DU1: Randi Wood | DV1: Rashmi Gupta | DW1: Rashmi Kottachery | DX1: Rashmi Rangdale | DY1: Rathika Jude | DZ1: Ratnasree Gudla | EA1: Reejaramani Subramani | EB1: Reema Rasheed | EC1: Reshmi Pulickal Radhakrishnan | ED1: Rima Loganathan | EE1: Rishi Goswami | EF1: Roja Punna | EG1: Rupali Bangar | EH1: Rutuja Rajput | EI1: Sabiha Khan | EJ1: Sai Santhya Ravikumar | EK1: Sangeetha Jeyabalan | EL1: Sanjana Mandal | EM1: Sara Abdelsayed | EN1: Saranya Sabarish | EO1: Sasikala Murugesan | EP1: Sathya Ezhilan | EQ1: Sathya Naveenraj | ER1: Selvakamatchi Rajamani | ES1: Shagida Nishwan | ET1: Sharanya Madhavan | EU1: Sharmila Lakshmipathy | EV1: Sharmila Raghavan | EW1: Siddhardha Yalavarthy | EX1: Sindhu Selvaraj | EY1: Sindhu Thanigesan | EZ1: Sireesha Gottimukkala | FA1: Snehal Choudhari | FB1: Snighdha Dave | FC1: Somdutta Paul | FD1: Sonali Gupta | FE1: Sonia Mohanty | FF1: Soumya kalyanaraman | FG1: Sowjanya Ravella | FH1: Sree Nalini Uduta | FI1: Sreedevi Salapu | FJ1: Srikanya R | FK1: Srilekha Kotte | FL1: Sripriyadarshini | FM1: Srividhyalakshmi Murugadass | FN1: Sruthi Arambachalil | FO1: Subasri Swaminathan | FP1: Subhanandhini Kumarasamy | FQ1: Subhina Bhaskar | FR1: subratha suresh kamat | FS1: Suchitra Rajesh | FT1: Sudesh Goel | FU1: Sunitha nara | FV1: Swathi Kodali | FW1: SWATHI LAKSHMI GUNDURU | FX1: Swati bartake | FY1: Swati Ghogare | FZ1: Sweety Ranka | GA1: Tapasi Rath | GB1: Tarshik Spurling | GC1: Tej Patel | GD1: Umamaheswari Shanmugam | GE1: Usha Devi Singaravelu | GF1: Vaishnavi Devi Bunja Dhinakaran | GG1: Valarmathi Magudeswaran | GH1: Valliammai Ramanathan | GI1: Vani Hanumantu | GJ1: Varsha Javali | GK1: Vasuda Rawal | GL1: Vasudha Kodi | GM1: Venkata Vemuri | GN1: Vidya Thirunavukkarasu | GO1: Vijayalakshmi Bhaskaran | GP1: Vyom Bhandari | GQ1: Yazhini Ravichandran | GR1: Kely
A2: Total Payout | B2: =SUM(C2:GR2) -> 174456.6 | C2: =IFERROR(HLOOKUP(C1,Index!C1:GR12,11,0),0) -> 4391.5 | D2: =IFERROR(HLOOKUP(D1,Index!D1:GS12,11,0),0) -> 4556.85 | E2: =IFERROR(HLOOKUP(E1,Index!E1:GT12,11,0),0) -> 8 | F2: =IFERROR(HLOOKUP(F1,Index!F1:GU12,11,0),0) -> 3530.15 | G2: =IFERROR(HLOOKUP(G1,Index!G1:GV12,11,0),0) -> 318.5 | H2: =IFERROR(HLOOKUP(H1,Index!H1:GW12,11,0),0) -> 1191.25 | I2: =IFERROR(HLOOKUP(I1,Index!I1:GX12,11,0),0) -> 3313.25 | J2: =IFERROR(HLOOKUP(J1,Index!J1:GY12,11,0),0) -> 10.5 | ... GR2: =IFERROR(HLOOKUP(GR1,Index!GR1:OG12,11,0),0) -> 4082
B3: =B2-Index!B11 -> 0

Sheet Arrears_Nov'25
A1: Process | B1: Total
A2: Datavant Arrears | B2: =SUM(C2:CL2) -> 0
A3: MRO Processing | B3: =SUM(C3:CL3) -> 0
A4: Verisma Arrears | B4: =SUM(C4:CL4) -> 0
A5: Total | B5: =SUM(B2:B4) -> 0 | C5: =SUM(C3:C4) -> 0 | D5: =SUM(D3:D4) -> 0 | E5: =SUM(E2:E4) -> 0 | F5: =SUM(F2:F4) -> 0 | G5: =SUM(G3:G4) -> 0

Sheet Payroll Verisma
A1: Date | B1: Day | C1: Overall
D2: Aanya | E2: Ahila Sundaresan | F2: Alekhya Pokuri | G2: Ambar Romero | H2: Amel Yousfi | I2: Amrita Singh | J2: Andrea Lorenzano | K2: Angayarkanni Kannan | L2: Angel Edwards | M2: Anitaben Patel | N2: Anjali Devunuri | O2: Anjana Vijayan | P2: Ankana Biswas Dutta | Q2: Anshu Dubey | R2: Anusha Cheerla | S2: Anusha Kulageri | T2: Anusha Prasannakumar | U2: Arcelia Finkelberg | V2: Atchaya Rangasamy Venugopal | W2: Azumi Van Scyoc | X2: Babitha Koraganti | Y2: Balasubramani Kandasamy | Z2: Cecilia Hendricks | AA2: Chandana Bathina | AB2: Chandini Yellamilli | AC2: Chinmaya Jyothi Pulikallu | AD2: Damion Newell | AE2: Deepika Chintaluri | AF2: Devi Prakash | AG2: Devicharitha Malapati | AH2: Dhanalakshmi Nelluri | AI2: Dhivya Shankar | AJ2: Dhivyalakshmi Vigneshwaran | AK2: Diksha Vijaykumar More | AL2: Divya Babu | AM2: Divya Manjeshwar kamath | AN2: Divya Shree | AO2: Erianna Lockhart | AP2: Faith Ujjwala Singh | AQ2: Fallyan Redd | AR2: Farheen Hasham | AS2: Farzana Shaik | AT2: Fnu Supriya | AU2: Foua Yang | AV2: Franklin C Onyedili | AW2: Gayatri Paramsivam | AX2: Geetalakshmi Govinthara Annadhurai | AY2: Gia Erica Coleman | AZ2: Hadjer Ikram Yousfi | BA2: Haley VanNamee | BB2: Harathi Nuvuru | BC2: Hetal Shah | BD2: I-Asia Newkirk | BE2: Infanta Clara Victor Anthony | BF2: Jaya Singh | BG2: Jayashree Swain | BH2: Jhou Yang | BI2: Jyothi Venkatasubramanya | BJ2: Kabila Sivasankar | BK2: Kavya Krishnappa | BL2: Kawanna Brown | BM2: Komala Renuka Prasad | BN2: Krishnaveni | BO2: Krithika Balasubramaniam | BP2: Lakshmi Neelima Duddula | BQ2: LaSere Reid Smith | BR2: LATHA BUSIREDDY | BS2: Latrice Adams | BT2: Lavanya Vigrahala | BU2: Laxmi Sirisha Penumecha | BV2: Lipsa Padhy | BW2: Lokeswari Gummadi | BX2: Madhana Sundari Vijayarajan | BY2: Madhavi Balineni | BZ2: Madhura Alva | CA2: Madhuri Padala | CB2: Maira Becham | CC2: Manda Talwekar | CD2: Manjunath JagadishPai | CE2: Mariko Huskey | CF2: Marilyn Brown | CG2: Marina Ibrahim | CH2: Mathangi Radhakrishnan | CI2: Michelle Cox | CJ2: Minakshi Deepak | CK2: Mojisha Mohandas | CL2: Monalisa Roy | CM2: Mool Chand | CN2: Naagarashikaa Vijayakumar | CO2: Naganandhini Ganapathimaran | CP2: Namita Mishra | CQ2: Namrata Sharma | CR2: Namratha Koratala | CS2: Narmadhadevi Dharmapalan | CT2: Neena Mathew Saravanakumar | CU2: Neha Aaggarwal | CV2: Nilopher Lopes | CW2: Nitha Chathoth Kunhikrishnan | CX2: Padmapriya krishnamoorthy | CY2: Palak Porwal | CZ2: Pavithra Balaji | DA2: Pavithra Manas Panda | DB2: Pavitra Rani Allam | DC2: Pooja Solanki | DD2: Poongothai Duraisamy | DE2: Pragyan Paramita Mohanty | DF2: Pranusha Dontineni | DG2: Prasana Kotagiri | DH2: Prathima Krishnamurthy Yadav | DI2: Prathima Lakkireddy | DJ2: PRAVALLIKA NUTHALAPATI | DK2: Priti Suman | DL2: Priyadarsini Baral | DM2: Priyanka Chandrikapure | DN2: Priyanka Dey Sarkar | DO2: Priyanka Gadar | DP2: Pushpaja Vullamgunta | DQ2: Rajameenakshi Sankarasubramanian | DR2: Rajeshwari Thammineni | DS2: Ramsheena Nadathalakkel | DT2: Ramya Muralidharan | DU2: Ramya Sudarshan Palavalli | DV2: Randi Wood | DW2: Rashmi Gupta | DX2: Rashmi Kottachery | DY2: Rashmi Rangdale | DZ2: Rathika Jude | EA2: Ratnasree Gudla | EB2: Reejaramani Subramani | EC2: Reema Rasheed | ED2: Reshmi Pulickal Radhakrishnan | EE2: Rima Loganathan | EF2: Rishi Goswami | EG2: Roja Punna | EH2: Rupali Bangar | EI2: Rutuja Rajput | EJ2: Sabiha Khan | EK2: Sai Santhya Ravikumar | EL2: Sangeetha Jeyabalan | EM2: Sanjana Mandal | EN2: Sara Abdelsayed | EO2: Saranya Sabarish | EP2: Sasikala Murugesan | EQ2: Sathya Ezhilan | ER2: Sathya Naveenraj | ES2: Selvakamatchi Rajamani | ET2: Shagida Nishwan | EU2: Sharanya Madhavan | EV2: Sharmila Lakshmipathy | EW2: Sharmila Raghavan | EX2: Siddhardha Yalavarthy | EY2: Sindhu Selvaraj | EZ2: Sindhu Thanigesan | FA2: Sireesha Gottimukkala | FB2: Snehal Choudhari | FC2: Snighdha Dave | FD2: Somdutta Paul | FE2: Sonali Gupta | FF2: Sonia Mohanty | FG2: Soumya kalyanaraman | FH2: Sowjanya Ravella | FI2: Sree Nalini Uduta | FJ2: Sreedevi Salapu | FK2: Srikanya R | FL2: Srilekha Kotte | FM2: Sripriyadarshini | FN2: Srividhyalakshmi Murugadass | FO2: Sruthi Arambachalil | FP2: Subasri Swaminathan | FQ2: Subhanandhini Kumarasamy | FR2: Subhina Bhaskar | FS2: subratha suresh kamat | FT2: Suchitra Rajesh | FU2: Sudesh Goel | FV2: Sunitha nara | FW2: Swathi Kodali | FX2: SWATHI LAKSHMI GUNDURU | FY2: Swati bartake | FZ2: Swati Ghogare | GA2: Sweety Ranka | GB2: Tapasi Rath | GC2: Tarshik Spurling | GD2: Tej Patel | GE2: Umamaheswari Shanmugam | GF2: Usha Devi Singaravelu | GG2: Vaishnavi Devi Bunja Dhinakaran | GH2: Valarmathi Magudeswaran | GI2: Valliammai Ramanathan | GJ2: Vani Hanumantu | GK2: Varsha Javali | GL2: Vasuda Rawal | GM2: Vasudha Kodi | GN2: Venkata Vemuri | GO2: Vidya Thirunavukkarasu | GP2: Vijayalakshmi Bhaskaran | GQ2: Vyom Bhandari | GR2: Yazhini Ravichandran
A3: ='Payroll MRO'!A3 -> 46023 | B3: =TEXT(A3,"DDD") -> Thu | C3: =SUM(D3:GV3) -> 814 | D3: 0 | E3: 0 | F3: 0 | G3: 0 | H3: 0 | I3: 0 | J3: 0 | K3: 0 | L3: 0 | M3: 0 | N3: 0 | O3: 0 | P3: 0 | Q3: 0 | R3: 0 | S3: 0 | T3: 56 | U3: 0 | V3: 0 | W3: 0 | X3: 0 | Y3: 0 | Z3: 62 | AA3: 0 | AB3: 0 | AC3: 0 | AD3: 0 | AE3: 0 | AF3: 0 | AG3: 0 | AH3: 0 | AI3: 0 | AJ3: 0 | AK3: 0 | AL3: 0 | AM3: 0 | AN3: 0 | AO3: 0 | AP3: 0 | AQ3: 0 | AR3: 0 | AS3: 0 | AT3: 0 | AU3: 0 | AV3: 0 | AW3: 0 | AX3: 0 | AY3: 0 | AZ3: 0 | BA3: 0 | BB3: 0 | BC3: 0 | BD3: 0 | BE3: 0 | BF3: 0 | BG3: 0 | BH3: 0 | BI3: 0 | BJ3: 0 | BK3: 0 | BL3: 0 | BM3: 0 | BN3: 10 | BO3: 0 | BP3: 0 | BQ3: 0 | BR3: 0 | BS3: 0 | BT3: 0 | BU3: 0 | BV3: 0 | BW3: 0 | BX3: 0 | BY3: 0 | BZ3: 0 | CA3: 0 | CB3: 0 | CC3: 0 | CD3: 0 | CE3: 0 | CF3: 0 | CG3: 0 | CH3: 8 | CI3: 0 | CJ3: 0 | CK3: 0 | CL3: 0 | CM3: 0 | CN3: 51 | CO3: 0 | CP3: 0 | CQ3: 0 | CR3: 10 | CS3: 0 | CT3: 0 | CU3: 0 | CV3: 0 | CW3: 0 | CX3: 0 | CY3: 0 | CZ3: 0 | DA3: 0 | DB3: 0 | DC3: 0 | DD3: 0 | DE3: 0 | DF3: 0 | DG3: 0 | DH3: 0 | DI3: 0 | DJ3: 0 | DK3: 69 | DL3: 0 | DM3: 0 | DN3: 0 | DO3: 0 | DP3: 0 | DQ3: 0 | DR3: 0 | DS3: 0 | DT3: 0 | DU3: 0 | DV3: 0 | DW3: 0 | DX3: 3 | DY3: 0 | DZ3: 0 | EA3: 0 | EB3: 0 | EC3: 0 | ED3: 0 | EE3: 0 | EF3: 0 | EG3: 0 | EH3: 0 | EI3: 0 | EJ3: 0 | EK3: 0 | EL3: 0 | EM3: 0 | EN3: 0 | EO3: 0 | EP3: 0 | EQ3: 0 | ER3: 0 | ES3: 0 | ET3: 0 | EU3: 0 | EV3: 0 | EW3: 0 | EX3: 0 | EY3: 0 | EZ3: 0 | FA3: 0 | FB3: 0 | FC3: 0 | FD3: 0 | FE3: 0 | FF3: 0 | FG3: 0 | FH3: 290 | FI3: 0 | FJ3: 0 | FK3: 0 | FL3: 0 | FM3: 0 | FN3: 0 | FO3: 0 | FP3: 0 | FQ3: 0 | FR3: 0 | FS3: 200 | FT3: 0 | FU3: 0 | FV3: 0 | FW3: 0 | FX3: 0 | FY3: 0 | FZ3: 0 | GA3: 0 | GB3: 0 | GC3: 0 | GD3: 0 | GE3: 28 | GF3: 0 | GG3: 0 | GH3: 0 | GI3: 0 | GJ3: 0 | GK3: 0 | GL3: 27 | GM3: 0 | GN3: 0 | GO3: 0 | GP3: 0 | GQ3: 0 | GR3: 0
A4: =A3+1 -> 46024 | B4: =TEXT(A4,"DDD") -> Fri | C4: =SUM(D4:GV4) -> 2443 | D4: 0 | E4: 0 | F4: 0 | G4: 0 | H4: 0 | I4: 0 | J4: 0 | K4: 0 | L4: 0 | M4: 0 | N4: 32 | O4: 0 | P4: 0 | Q4: 0 | R4: 0 | S4: 57 | T4: 136 | U4: 0 | V4: 0 | W4: 0 | X4: 0 | Y4: 0 | Z4: 0 | AA4: 0 | AB4: 0 | AC4: 0 | AD4: 36 | AE4: 0 | AF4: 0 | AG4: 0 | AH4: 0 | AI4: 0 | AJ4: 0 | AK4: 0 | AL4: 0 | AM4: 0 | AN4: 0 | AO4: 0 | AP4: 0 | AQ4: 0 | AR4: 0 | AS4: 0 | AT4: 0 | AU4: 0 | AV4: 10 | AW4: 30 | AX4: 82 | AY4: 17 | AZ4: 0 | BA4: 87 | BB4: 0 | BC4: 0 | BD4: 250 | BE4: 40 | BF4: 0 | BG4: 0 | BH4: 0 | BI4: 72 | BJ4: 0 | BK4: 0 | BL4: 0 | BM4: 0 | BN4: 0 | BO4: 0 | BP4: 0 | BQ4: 0 | BR4: 0 | BS4: 38 | BT4: 0 | BU4: 0 | BV4: 0 | BW4: 0 | BX4: 0 | BY4: 0 | BZ4: 13 | CA4: 0 | CB4: 0 | CC4: 26 | CD4: 0 | CE4: 0 | CF4: 17 | CG4: 0 | CH4: 47 | CI4: 0 | CJ4: 0 | CK4: 0 | CL4: 0 | CM4: 0 | CN4: 57 | CO4: 0 | CP4: 0 | CQ4: 0 | CR4: 25 | CS4: 5 | CT4: 0 | CU4: 0 | CV4: 0 | CW4: 0 | CX4: 0 | CY4: 0 | CZ4: 33 | DA4: 43 | DB4: 0 | DC4: 0 | DD4: 0 | DE4: 0 | DF4: 0 | DG4: 0 | DH4: 0 | DI4: 0 | DJ4: 0 | DK4: 0 | DL4: 20 | DM4: 0 | DN4: 28 | DO4: 0 | DP4: 0 | DQ4: 0 | DR4: 0 | DS4: 46 | DT4: 0 | DU4: 24 | DV4: 0 | DW4: 0 | DX4: 28 | DY4: 0 | DZ4: 70 | EA4: 0 | EB4: 20 | EC4: 0 | ED4: 0 | EE4: 0 | EF4: 0 | EG4: 0 | EH4: 0 | EI4: 0 | EJ4: 53 | EK4: 0 | EL4: 0 | EM4: 0 | EN4: 0 | EO4: 55 | EP4: 0 | EQ4: 0 | ER4: 0 | ES4: 0 | ET4: 0 | EU4: 0 | EV4: 47 | EW4: 0 | EX4: 38 | EY4: 0 | EZ4: 24 | FA4: 0 | FB4: 0 | FC4: 0 | FD4: 0 | FE4: 0 | FF4: 0 | FG4: 0 | FH4: 352 | FI4: 0 | FJ4: 0 | FK4: 0 | FL4: 0 | FM4: 0 | FN4: 0 | FO4: 16 | FP4: 0 | FQ4: 71 | FR4: 0 | FS4: 23 | FT4: 94 | FU4: 0 | FV4: 0 | FW4: 0 | FX4: 0 | FY4: 35 | FZ4: 78 | GA4: 0 | GB4: 0 | GC4: 0 | GD4: 0 | GE4: 66 | GF4: 0 | GG4: 0 | GH4: 0 | GI4: 0 | GJ4: 0 | GK4: 54 | GL4: 0 | GM4: 0 | GN4: 0 | GO4: 48 | GP4: 0 | GQ4: 0 | GR4: 0
A5: =A4+1 -> 46025 | B5: =TEXT(A5,"DDD") -> Sat | C5: =SUM(D5:GV5) -> 250 | D5: 0 | E5: 0 | F5: 0 | G5: 0 | H5: 0 | I5: 0 | J5: 0 | K5: 0 | L5: 0 | M5: 0 | N5: 0 | O5: 0 | P5: 0 | Q5: 0 | R5: 0 | S5: 0 | T5: 22 | U5: 0 | V5: 0 | W5: 0 | X5: 0 | Y5: 0 | Z5: 0 | AA5: 0 | AB5: 0 | AC5: 0 | AD5: 0 | AE5: 0 | AF5: 0 | AG5: 0 | AH5: 42 | AI5: 0 | AJ5: 0 | AK5: 0 | AL5: 0 | AM5: 0 | AN5: 0 | AO5: 0 | AP5: 0 | AQ5: 0 | AR5: 0 | AS5: 0 | AT5: 0 | AU5: 0 | AV5: 0 | AW5: 0 | AX5: 0 | AY5: 0 | AZ5: 0 | BA5: 0 | BB5: 0 | BC5: 0 | BD5: 0 | BE5: 0 | BF5: 0 | BG5: 0 | BH5: 0 | BI5: 0 | BJ5: 0 | BK5: 0 | BL5: 0 | BM5: 0 | BN5: 0 | BO5: 0 | BP5: 0 | BQ5: 0 | BR5: 0 | BS5: 0 | BT5: 0 | BU5: 0 | BV5: 0 | BW5: 0 | BX5: 0 | BY5: 0 | BZ5: 0 | CA5: 0 | CB5: 0 | CC5: 0 | CD5: 35 | CE5: 0 | CF5: 0 | CG5: 0 | CH5: 0 | CI5: 0 | CJ5: 0 | CK5: 0 | CL5: 0 | CM5: 0 | CN5: 0 | CO5: 0 | CP5: 0 | CQ5: 0 | CR5: 25 | CS5: 10 | CT5: 0 | CU5: 0 | CV5: 0 | CW5: 0 | CX5: 0 | CY5: 0 | CZ5: 0 | DA5: 0 | DB5: 0 | DC5: 0 | DD5: 0 | DE5: 0 | DF5: 0 | DG5: 0 | DH5: 0 | DI5: 0 | DJ5: 0 | DK5: 0 | DL5: 0 | DM5: 0 | DN5: 0 | DO5: 0 | DP5: 0 | DQ5: 0 | DR5: 0 | DS5: 36 | DT5: 0 | DU5: 0 | DV5: 0 | DW5: 0 | DX5: 0 | DY5: 0 | DZ5: 0 | EA5: 0 | EB5: 0 | EC5: 0 | ED5: 0 | EE5: 0 | EF5: 0 | EG5: 0 | EH5: 0 | EI5: 0 | EJ5: 0 | EK5: 0 | EL5: 0 | EM5: 0 | EN5: 0 | EO5: 0 | EP5: 0 | EQ5: 0 | ER5: 0 | ES5: 0 | ET5: 0 | EU5: 0 | EV5: 0 | EW5: 8 | EX5: 0 | EY5: 0 | EZ5: 0 | FA5: 0 | FB5: 0 | FC5: 0 | FD5: 0 | FE5: 0 | FF5: 0 | FG5: 0 | FH5: 72 | FI5: 0 | FJ5: 0 | FK5: 0 | FL5: 0 | FM5: 0 | FN5: 0 | FO5: 0 | FP5: 0 | FQ5: 0 | FR5: 0 | FS5: 0 | FT5: 0 | FU5: 0 | FV5: 0 | FW5: 0 | FX5: 0 | FY5: 0 | FZ5: 0 | GA5: 0 | GB5: 0 | GC5: 0 | GD5: 0 | GE5: 0 | GF5: 0 | GG5: 0 | GH5: 0 | GI5: 0 | GJ5: 0 | GK5: 0 | GL5: 0 | GM5: 0 | GN5: 0 | GO5: 0 | GP5: 0 | GQ5: 0 | GR5: 0
A6: =A5+1 -> 46026 | B6: =TEXT(A6,"DDD") -> Sun | C6: =SUM(D6:GV6) -> 73 | D6: 0 | E6: 0 | F6: 0 | G6: 0 | H6: 0 | I6: 0 | J6: 0 | K6: 0 | L6: 0 | M6: 0 | N6: 0 | O6: 0 | P6: 0 | Q6: 0 | R6: 0 | S6: 0 | T6: 0 | U6: 0 | V6: 0 | W6: 0 | X6: 0 | Y6: 0 | Z6: 0 | AA6: 0 | AB6: 0 | AC6: 0 | AD6: 0 | AE6: 0 | AF6: 0 | AG6: 0 | AH6: 0 | AI6: 0 | AJ6: 0 | AK6: 0 | AL6: 0 | AM6: 0 | AN6: 0 | AO6: 0 | AP6: 0 | AQ6: 0 | AR6: 0 | AS6: 0 | AT6: 0 | AU6: 0 | AV6: 0 | AW6: 0 | AX6: 0 | AY6: 0 | AZ6: 0 | BA6: 0 | BB6: 0 | BC6: 0 | BD6: 0 | BE6: 0 | BF6: 0 | BG6: 0 | BH6: 0 | BI6: 0 | BJ6: 0 | BK6: 0 | BL6: 0 | BM6: 0 | BN6: 0 | BO6: 0 | BP6: 0 | BQ6: 0 | BR6: 0 | BS6: 0 | BT6: 0 | BU6: 0 | BV6: 0 | BW6: 0 | BX6: 0 | BY6: 0 | BZ6: 0 | CA6: 0 | CB6: 0 | CC6: 0 | CD6: 0 | CE6: 0 | CF6: 0 | CG6: 0 | CH6: 9 | CI6: 0 | CJ6: 0 | CK6: 0 | CL6: 0 | CM6: 0 | CN6: 0 | CO6: 0 | CP6: 0 | CQ6: 0 | CR6: 9 | CS6: 6 | CT6: 0 | CU6: 0 | CV6: 0 | CW6: 0 | CX6: 0 | CY6: 0 | CZ6: 0 | DA6: 0 | DB6: 0 | DC6: 0 | DD6: 0 | DE6: 0 | DF6: 0 | DG6: 0 | DH6: 0 | DI6: 0 | DJ6: 0 | DK6: 0 | DL6: 0 | DM6: 0 | DN6: 0 | DO6: 0 | DP6: 0 | DQ6: 0 | DR6: 0 | DS6: 0 | DT6: 0 | DU6: 0 | DV6: 0 | DW6: 0 | DX6: 0 | DY6: 0 | DZ6: 0 | EA6: 0 | EB6: 0 | EC6: 0 | ED6: 0 | EE6: 0 | EF6: 0 | EG6: 0 | EH6: 0 | EI6: 0 | EJ6: 0 | EK6: 0 | EL6: 0 | EM6: 0 | EN6: 0 | EO6: 0 | EP6: 0 | EQ6: 0 | ER6: 0 | ES6: 0 | ET6: 0 | EU6: 0 | EV6: 0 | EW6: 0 | EX6: 0 | EY6: 0 | EZ6: 0 | FA6: 0 | FB6: 0 | FC6: 0 | FD6: 0 | FE6: 0 | FF6: 0 | FG6: 0 | FH6: 17 | FI6: 0 | FJ6: 0 | FK6: 0 | FL6: 0 | FM6: 0 | FN6: 0 | FO6: 0 | FP6: 0 | FQ6: 0 | FR6: 0 | FS6: 0 | FT6: 0 | FU6: 0 | FV6: 0 | FW6: 0 | FX6: 0 | FY6: 0 | FZ6: 0 | GA6: 0 | GB6: 0 | GC6: 0 | GD6: 0 | GE6: 32 | GF6: 0 | GG6: 0 | GH6: 0 | GI6: 0 | GJ6: 0 | GK6: 0 | GL6: 0 | GM6: 0 | GN6: 0 | GO6: 0 | GP6: 0 | GQ6: 0 | GR6: 0
A7: =A6+1 -> 46027 | B7: =TEXT(A7,"DDD") -> Mon | C7: =SUM(D7:GV7) -> 2531 | D7: 0 | E7: 0 | F7: 0 | G7: 0 | H7: 0 | I7: 0 | J7: 0 | K7: 0 | L7: 0 | M7: 0 | N7: 16 | O7: 66 | P7: 0 | Q7: 0 | R7: 0 | S7: 53 | T7: 96 | U7: 17 | V7: 0 | W7: 0 | X7: 0 | Y7: 0 | Z7: 51 | AA7: 0 | AB7: 0 | AC7: 0 | AD7: 74 | AE7: 0 | AF7: 0 | AG7: 0 | AH7: 39 | AI7: 0 | AJ7: 0 | AK7: 0 | AL7: 0 | AM7: 0 | AN7: 0 | AO7: 0 | AP7: 0 | AQ7: 0 | AR7: 0 | AS7: 0 | AT7: 0 | AU7: 27 | AV7: 21 | AW7: 30 | AX7: 31 | AY7: 0 | AZ7: 0 | BA7: 75 | BB7: 0 | BC7: 0 | BD7: 234 | BE7: 23 | BF7: 0 | BG7: 0 | BH7: 0 | BI7: 17 | BJ7: 0 | BK7: 0 | BL7: 0 | BM7: 0 | BN7: 0 | BO7: 0 | BP7: 0 | BQ7: 0 | BR7: 0 | BS7: 46 | BT7: 0 | BU7: 0 | BV7: 0 | BW7: 0 | BX7: 0 | BY7: 0 | BZ7: 0 | CA7: 0 | CB7: 0 | CC7: 17 | CD7: 204 | CE7: 0 | CF7: 21 | CG7: 0 | CH7: 18 | CI7: 0 | CJ7: 0 | CK7: 0 | CL7: 0 | CM7: 0 | CN7: 0 | CO7: 0 | CP7: 0 | CQ7: 0 | CR7: 0 | CS7: 5 | CT7: 22 | CU7: 0 | CV7: 0 | CW7: 0 | CX7: 0 | CY7: 0 | CZ7: 30 | DA7: 33 | DB7: 0 | DC7: 0 | DD7: 0 | DE7: 0 | DF7: 0 | DG7: 0 | DH7: 0 | DI7: 0 | DJ7: 0 | DK7: 0 | DL7: 2 | DM7: 0 | DN7: 75 | DO7: 0 | DP7: 0 | DQ7: 0 | DR7: 0 | DS7: 83 | DT7: 0 | DU7: 21 | DV7: 0 | DW7: 0 | DX7: 29 | DY7: 49 | DZ7: 135 | EA7: 0 | EB7: 24 | EC7: 0 | ED7: 0 | EE7: 0 | EF7: 0 | EG7: 0 | EH7: 0 | EI7: 0 | EJ7: 38 | EK7: 0 | EL7: 0 | EM7: 0 | EN7: 0 | EO7: 40 | EP7: 0 | EQ7: 0 | ER7: 0 | ES7: 0 | ET7: 0 | EU7: 18 | EV7: 12 | EW7: 36 | EX7: 26 | EY7: 0 | EZ7: 5 | FA7: 0 | FB7: 0 | FC7: 0 | FD7: 20 | FE7: 0 | FF7: 0 | FG7: 0 | FH7: 213 | FI7: 0 | FJ7: 0 | FK7: 0 | FL7: 0 | FM7: 0 | FN7: 0 | FO7: 40 | FP7: 0 | FQ7: 55 | FR7: 0 | FS7: 42 | FT7: 32 | FU7: 0 | FV7: 0 | FW7: 0 | FX7: 0 | FY7: 35 | FZ7: 25 | GA7: 0 | GB7: 0 | GC7: 0 | GD7: 0 | GE7: 41 | GF7: 0 | GG7: 0 | GH7: 0 | GI7: 31 | GJ7: 0 | GK7: 41 | GL7: 66 | GM7: 0 | GN7: 0 | GO7: 31 | GP7: 0 | GQ7: 0 | GR7: 0
A8: =A7+1 -> 46028 | B8: =TEXT(A8,"DDD") -> Tue | C8: =SUM(D8:GV8) -> 2614 | D8: 0 | E8: 27 | F8: 0 | G8: 0 | H8: 0 | I8: 0 | J8: 0 | K8: 0 | L8: 0 | M8: 0 | N8: 12 | O8: 76 | P8: 0 | Q8: 0 | R8: 0 | S8: 53 | T8: 154 | U8: 16 | V8: 0 | W8: 0 | X8: 0 | Y8: 0 | Z8: 0 | AA8: 0 | AB8: 0 | AC8: 0 | AD8: 84 | AE8: 0 | AF8: 0 | AG8: 0 | AH8: 0 | AI8: 0 | AJ8: 0 | AK8: 11 | AL8: 0 | AM8: 0 | AN8: 0 | AO8: 33 | AP8: 0 | AQ8: 0 | AR8: 0 | AS8: 0 | AT8: 0 | AU8: 35 | AV8: 0 | AW8: 42 | AX8: 69 | AY8: 26 | AZ8: 0 | BA8: 69 | BB8: 0 | BC8: 0 | BD8: 92 | BE8: 0 | BF8: 0 | BG8: 0 | BH8: 0 | BI8: 23 | BJ8: 0 | BK8: 0 | BL8: 0 | BM8: 0 | BN8: 0 | BO8: 0 | BP8: 0 | BQ8: 0 | BR8: 0 | BS8: 10 | BT8: 0 | BU8: 0 | BV8: 0 | BW8: 0 | BX8: 0 | BY8: 0 | BZ8: 0 | CA8: 0 | CB8: 0 | CC8: 32 | CD8: 171 | CE8: 0 | CF8: 14 | CG8: 0 | CH8: 19 | CI8: 0 | CJ8: 0 | CK8: 0 | CL8: 0 | CM8: 0 | CN8: 27 | CO8: 0 | CP8: 0 | CQ8: 0 | CR8: 2 | CS8: 6 | CT8: 10 | CU8: 0 | CV8: 0 | CW8: 0 | CX8: 0 | CY8: 0 | CZ8: 40 | DA8: 34 | DB8: 0 | DC8: 0 | DD8: 23 | DE8: 0 | DF8: 0 | DG8: 0 | DH8: 0 | DI8: 0 | DJ8: 0 | DK8: 51 | DL8: 25 | DM8: 0 | DN8: 108 | DO8: 0 | DP8: 0 | DQ8: 0 | DR8: 0 | DS8: 20 | DT8: 0 | DU8: 28 | DV8: 0 | DW8: 0 | DX8: 30 | DY8: 47 | DZ8: 79 | EA8: 0 | EB8: 28 | EC8: 0 | ED8: 0 | EE8: 0 | EF8: 0 | EG8: 0 | EH8: 12 | EI8: 0 | EJ8: 41 | EK8: 0 | EL8: 0 | EM8: 0 | EN8: 0 | EO8: 48 | EP8: 0 | EQ8: 0 | ER8: 0 | ES8: 0 | ET8: 0 | EU8: 14 | EV8: 21 | EW8: 0 | EX8: 42 | EY8: 0 | EZ8: 17 | FA8: 0 | FB8: 15 | FC8: 0 | FD8: 16 | FE8: 0 | FF8: 0 | FG8: 0 | FH8: 165 | FI8: 0 | FJ8: 0 | FK8: 0 | FL8: 0 | FM8: 0 | FN8: 0 | FO8: 40 | FP8: 0 | FQ8: 83 | FR8: 0 | FS8: 70 | FT8: 35 | FU8: 0 | FV8: 0 | FW8: 0 | FX8: 0 | FY8: 15 | FZ8: 45 | GA8: 0 | GB8: 0 | GC8: 0 | GD8: 0 | GE8: 78 | GF8: 0 | GG8: 0 | GH8: 0 | GI8: 0 | GJ8: 0 | GK8: 85 | GL8: 81 | GM8: 0 | GN8: 0 | GO8: 65 | GP8: 0 | GQ8: 0 | GR8: 0
A9: =A8+1 -> 46029 | B9: =TEXT(A9,"DDD") -> Wed | C9: =SUM(D9:GV9) -> 2604 | D9: 0 | E9: 0 | F9: 0 | G9: 0 | H9: 0 | I9: 0 | J9: 0 | K9: 0 | L9: 0 | M9: 0 | N9: 50 | O9: 71 | P9: 0 | Q9: 0 | R9: 0 | S9: 58 | T9: 157 | U9: 12 | V9: 0 | W9: 0 | X9: 0 | Y9: 0 | Z9: 57 | AA9: 0 | AB9: 0 | AC9: 0 | AD9: 44 | AE9: 0 | AF9: 0 | AG9: 0 | AH9: 0 | AI9: 0 | AJ9: 0 | AK9: 10 | AL9: 0 | AM9: 0 | AN9: 0 | AO9: 0 | AP9: 0 | AQ9: 0 | AR9: 0 | AS9: 0 | AT9: 0 | AU9: 36 | AV9: 32 | AW9: 45 | AX9: 53 | AY9: 11 | AZ9: 0 | BA9: 79 | BB9: 0 | BC9: 0 | BD9: 70 | BE9: 38 | BF9: 0 | BG9: 0 | BH9: 16 | BI9: 41 | BJ9: 0 | BK9: 0 | BL9: 0 | BM9: 0 | BN9: 0 | BO9: 0 | BP9: 0 | BQ9: 0 | BR9: 0 | BS9: 0 | BT9: 0 | BU9: 0 | BV9: 0 | BW9: 0 | BX9: 0 | BY9: 0 | BZ9: 0 | CA9: 0 | CB9: 0 | CC9: 29 | CD9: 155 | CE9: 0 | CF9: 13 | CG9: 0 | CH9: 50 | CI9: 0 | CJ9: 0 | CK9: 0 | CL9: 0 | CM9: 0 | CN9: 29 | CO9: 0 | CP9: 0 | CQ9: 0 | CR9: 0 | CS9: 8 | CT9: 30 | CU9: 0 | CV9: 0 | CW9: 0 | CX9: 0 | CY9: 0 | CZ9: 48 | DA9: 32 | DB9: 0 | DC9: 0 | DD9: 30 | DE9: 0 | DF9: 0 | DG9: 0 | DH9: 0 | DI9: 0 | DJ9: 0 | DK9: 0 | DL9: 11 | DM9: 0 | DN9: 69 | DO9: 9 | DP9: 1 | DQ9: 0 | DR9: 0 | DS9: 31 | DT9: 0 | DU9: 22 | DV9: 0 | DW9: 0 | DX9: 23 | DY9: 52 | DZ9: 43 | EA9: 0 | EB9: 31 | EC9: 0 | ED9: 0 | EE9: 0 | EF9: 0 | EG9: 0 | EH9: 2 | EI9: 0 | EJ9: 43 | EK9: 24 | EL9: 0 | EM9: 0 | EN9: 0 | EO9: 39 | EP9: 0 | EQ9: 0 | ER9: 0 | ES9: 0 | ET9: 0 | EU9: 84 | EV9: 75 | EW9: 42 | EX9: 17 | EY9: 15 | EZ9: 21 | FA9: 0 | FB9: 20 | FC9: 0 | FD9: 15 | FE9: 0 | FF9: 0 | FG9: 0 | FH9: 109 | FI9: 0 | FJ9: 0 | FK9: 0 | FL9: 0 | FM9: 0 | FN9: 0 | FO9: 54 | FP9: 0 | FQ9: 81 | FR9: 0 | FS9: 71 | FT9: 36 | FU9: 0 | FV9: 0 | FW9: 0 | FX9: 0 | FY9: 0 | FZ9: 46 | GA9: 0 | GB9: 0 | GC9: 0 | GD9: 0 | GE9: 55 | GF9: 0 | GG9: 0 | GH9: 0 | GI9: 0 | GJ9: 0 | GK9: 80 | GL9: 30 | GM9: 0 | GN9: 0 | GO9: 49 | GP9: 0 | GQ9: 0 | GR9: 0
A10: =A9+1 -> 46030 | B10: =TEXT(A10,"DDD") -> Thu | C10: =SUM(D10:GV10) -> 2695 | D10: 0 | E10: 16 | F10: 0 | G10: 0 | H10: 0 | I10: 0 | J10: 0 | K10: 0 | L10: 0 | M10: 0 | N10: 56 | O10: 60 | P10: 0 | Q10: 0 | R10: 0 | S10: 59 | T10: 149 | U10: 24 | V10: 0 | W10: 0 | X10: 0 | Y10: 0 | Z10: 53 | AA10: 0 | AB10: 0 | AC10: 0 | AD10: 54 | AE10: 0 | AF10: 0 | AG10: 0 | AH10: 0 | AI10: 0 | AJ10: 0 | AK10: 15 | AL10: 0 | AM10: 0 | AN10: 0 | AO10: 0 | AP10: 0 | AQ10: 0 | AR10: 0 | AS10: 0 | AT10: 0 | AU10: 29 | AV10: 0 | AW10: 45 | AX10: 72 | AY10: 4 | AZ10: 0 | BA10: 63 | BB10: 0 | BC10: 0 | BD10: 83 | BE10: 29 | BF10: 0 | BG10: 0 | BH10: 11 | BI10: 37 | BJ10: 0 | BK10: 0 | BL10: 0 | BM10: 0 | BN10: 0 | BO10: 0 | BP10: 0 | BQ10: 0 | BR10: 0 | BS10: 10 | BT10: 0 | BU10: 0 | BV10: 0 | BW10: 0 | BX10: 0 | BY10: 0 | BZ10: 0 | CA10: 0 | CB10: 0 | CC10: 32 | CD10: 307 | CE10: 0 | CF10: 7 | CG10: 0 | CH10: 57 | CI10: 0 | CJ10: 0 | CK10: 0 | CL10: 0 | CM10: 0 | CN10: 47 | CO10: 0 | CP10: 0 | CQ10: 0 | CR10: 0 | CS10: 2 | CT10: 30 | CU10: 0 | CV10: 0 | CW10: 0 | CX10: 0 | CY10: 0 | CZ10: 5 | DA10: 52 | DB10: 0 | DC10: 0 | DD10: 40 | DE10: 0 | DF10: 0 | DG10: 0 | DH10: 0 | DI10: 0 | DJ10: 0 | DK10: 4 | DL10: 16 | DM10: 0 | DN10: 103 | DO10: 7 | DP10: 8 | DQ10: 0 | DR10: 0 | DS10: 42 | DT10: 0 | DU10: 22 | DV10: 0 | DW10: 0 | DX10: 22 | DY10: 46 | DZ10: 0 | EA10: 0 | EB10: 36 | EC10: 0 | ED10: 0 | EE10: 0 | EF10: 0 | EG10: 0 | EH10: 0 | EI10: 0 | EJ10: 33 | EK10: 10 | EL10: 0 | EM10: 0 | EN10: 0 | EO10: 27 | EP10: 0 | EQ10: 0 | ER10: 0 | ES10: 0 | ET10: 0 | EU10: 56 | EV10: 64 | EW10: 20 | EX10: 31 | EY10: 29 | EZ10: 6 | FA10: 0 | FB10: 7 | FC10: 0 | FD10: 20 | FE10: 0 | FF10: 0 | FG10: 0 | FH10: 131 | FI10: 0 | FJ10: 0 | FK10: 0 | FL10: 0 | FM10: 0 | FN10: 0 | FO10: 46 | FP10: 0 | FQ10: 102 | FR10: 0 | FS10: 17 | FT10: 19 | FU10: 0 | FV10: 0 | FW10: 0 | FX10: 0 | FY10: 0 | FZ10: 37 | GA10: 0 | GB10: 0 | GC10: 0 | GD10: 0 | GE10: 58 | GF10: 0 | GG10: 0 | GH10: 0 | GI10: 21 | GJ10: 0 | GK10: 75 | GL10: 68 | GM10: 0 | GN10: 0 | GO10: 64 | GP10: 0 | GQ10: 0 | GR10: 0
A11: =A10+1 -> 46031 | B11: =TEXT(A11,"DDD") -> Fri | C11: =SUM(D11:GV11) -> 2734 | D11: 0 | E11: 0 | F11: 0 | G11: 0 | H11: 0 | I11: 0 | J11: 0 | K11: 0 | L11: 0 | M11: 0 | N11: 69 | O11: 75 | P11: 0 | Q11: 0 | R11: 0 | S11: 56 | T11: 144 | U11: 6 | V11: 0 | W11: 0 | X11: 0 | Y11: 0 | Z11: 51 | AA11: 0 | AB11: 0 | AC11: 0 | AD11: 51 | AE11: 0 | AF11: 0 | AG11: 0 | AH11: 0 | AI11: 0 | AJ11: 0 | AK11: 0 | AL11: 0 | AM11: 0 | AN11: 0 | AO11: 0 | AP11: 0 | AQ11: 0 | AR11: 0 | AS11: 0 | AT11: 0 | AU11: 44 | AV11: 9 | AW11: 42 | AX11: 49 | AY11: 0 | AZ11: 0 | BA11: 60 | BB11: 0 | BC11: 0 | BD11: 95 | BE11: 17 | BF11: 0 | BG11: 0 | BH11: 25 | BI11: 52 | BJ11: 0 | BK11: 0 | BL11: 0 | BM11: 0 | BN11: 0 | BO11: 0 | BP11: 0 | BQ11: 0 | BR11: 0 | BS11: 15 | BT11: 0 | BU11: 0 | BV11: 0 | BW11: 0 | BX11: 0 | BY11: 0 | BZ11: 0 | CA11: 0 | CB11: 0 | CC11: 41 | CD11: 251 | CE11: 0 | CF11: 0 | CG11: 0 | CH11: 39 | CI11: 0 | CJ11: 0 | CK11: 0 | CL11: 0 | CM11: 0 | CN11: 41 | CO11: 0 | CP11: 0 | CQ11: 0 | CR11: 0 | CS11: 2 | CT11: 25 | CU11: 0 | CV11: 0 | CW11: 0 | CX11: 0 | CY11: 0 | CZ11: 0 | DA11: 58 | DB11: 0 | DC11: 0 | DD11: 30 | DE11: 0 | DF11: 0 | DG11: 0 | DH11: 0 | DI11: 0 | DJ11: 0 | DK11: 0 | DL11: 8 | DM11: 0 | DN11: 55 | DO11: 14 | DP11: 6 | DQ11: 0 | DR11: 0 | DS11: 32 | DT11: 0 | DU11: 0 | DV11: 0 | DW11: 0 | DX11: 34 | DY11: 60 | DZ11: 12 | EA11: 0 | EB11: 45 | EC11: 0 | ED11: 0 | EE11: 0 | EF11: 0 | EG11: 0 | EH11: 0 | EI11: 0 | EJ11: 29 | EK11: 34 | EL11: 0 | EM11: 0 | EN11: 0 | EO11: 43 | EP11: 0 | EQ11: 0 | ER11: 0 | ES11: 0 | ET11: 0 | EU11: 62 | EV11: 49 | EW11: 47 | EX11: 36 | EY11: 0 | EZ11: 17 | FA11: 0 | FB11: 0 | FC11: 0 | FD11: 0 | FE11: 0 | FF11: 0 | FG11: 0 | FH11: 251 | FI11: 0 | FJ11: 0 | FK11: 0 | FL11: 0 | FM11: 0 | FN11: 0 | FO11: 0 | FP11: 0 | FQ11: 116 | FR11: 0 | FS11: 50 | FT11: 61 | FU11: 0 | FV11: 0 | FW11: 0 | FX11: 0 | FY11: 0 | FZ11: 73 | GA11: 0 | GB11: 0 | GC11: 0 | GD11: 0 | GE11: 84 | GF11: 15 | GG11: 0 | GH11: 0 | GI11: 11 | GJ11: 0 | GK11: 60 | GL11: 37 | GM11: 0 | GN11: 0 | GO11: 46 | GP11: 0 | GQ11: 0 | GR11: 0
A12: =A11+1 -> 46032 | B12: =TEXT(A12,"DDD") -> Sat | C12: =SUM(D12:GV12) -> 207 | D12: 0 | E12: 0 | F12: 0 | G12: 0 | H12: 0 | I12: 0 | J12: 0 | K12: 0 | L12: 0 | M12: 0 | N12: 0 | O12: 0 | P12: 0 | Q12: 0 | R12: 0 | S12: 0 | T12: 51 | U12: 0 | V12: 0 | W12: 0 | X12: 0 | Y12: 0 | Z12: 7 | AA12: 0 | AB12: 0 | AC12: 0 | AD12: 0 | AE12: 0 | AF12: 0 | AG12: 0 | AH12: 0 | AI12: 0 | AJ12: 0 | AK12: 0 | AL12: 0 | AM12: 0 | AN12: 0 | AO12: 0 | AP12: 0 | AQ12: 0 | AR12: 0 | AS12: 0 | AT12: 0 | AU12: 0 | AV12: 0 | AW12: 0 | AX12: 12 | AY12: 0 | AZ12: 0 | BA12: 0 | BB12: 0 | BC12: 0 | BD12: 0 | BE12: 0 | BF12: 0 | BG12: 0 | BH12: 0 | BI12: 0 | BJ12: 0 | BK12: 0 | BL12: 0 | BM12: 0 | BN12: 0 | BO12: 0 | BP12: 0 | BQ12: 0 | BR12: 0 | BS12: 0 | BT12: 0 | BU12: 0 | BV12: 0 | BW12: 0 | BX12: 0 | BY12: 0 | BZ12: 0 | CA12: 0 | CB12: 0 | CC12: 0 | CD12: 24 | CE12: 0 | CF12: 0 | CG12: 0 | CH12: 0 | CI12: 0 | CJ12: 0 | CK12: 0 | CL12: 0 | CM12: 0 | CN12: 0 | CO12: 0 | CP12: 0 | CQ12: 0 | CR12: 0 | CS12: 0 | CT12: 0 | CU12: 0 | CV12: 0 | CW12: 0 | CX12: 0 | CY12: 0 | CZ12: 0 | DA12: 0 | DB12: 0 | DC12: 0 | DD12: 0 | DE12: 0 | DF12: 0 | DG12: 0 | DH12: 0 | DI12: 0 | DJ12: 0 | DK12: 0 | DL12: 0 | DM12: 0 | DN12: 0 | DO12: 0 | DP12: 0 | DQ12: 0 | DR12: 0 | DS12: 0 | DT12: 0 | DU12: 7 | DV12: 0 | DW12: 0 | DX12: 0 | DY12: 0 | DZ12: 0 | EA12: 0 | EB12: 0 | EC12: 0 | ED12: 0 | EE12: 0 | EF12: 0 | EG12: 0 | EH12: 0 | EI12: 0 | EJ12: 0 | EK12: 0 | EL12: 0 | EM12: 0 | EN12: 0 | EO12: 0 | EP12: 0 | EQ12: 0 | ER12: 0 | ES12: 0 | ET12: 0 | EU12: 0 | EV12: 0 | EW12: 0 | EX12: 0 | EY12: 0 | EZ12: 0 | FA12: 0 | FB12: 0 | FC12: 0 | FD12: 0 | FE12: 0 | FF12: 0 | FG12: 0 | FH12: 0 | FI12: 0 | FJ12: 0 | FK12: 0 | FL12: 0 | FM12: 0 | FN12: 0 | FO12: 0 | FP12: 0 | FQ12: 66 | FR12: 0 | FS12: 0 | FT12: 0 | FU12: 0 | FV12: 0 | FW12: 0 | FX12: 0 | FY12: 0 | FZ12: 0 | GA12: 0 | GB12: 0 | GC12: 0 | GD12: 0 | GE12: 40 | GF12: 0 | GG12: 0 | GH12: 0 | GI12: 0 | GJ12: 0 | GK12: 0 | GL12: 0 | GM12: 0 | GN12: 0 | GO12: 0 | GP12: 0 | GQ12: 0 | GR12: 0
A13: =A12+1 -> 46033 | B13: =TEXT(A13,"DDD") -> Sun | C13: =SUM(D13:GV13) -> 156 | D13: 0 | E13: 0 | F13: 0 | G13: 0 | H13: 0 | I13: 0 | J13: 0 | K13: 0 | L13: 0 | M13: 0 | N13: 0 | O13: 0 | P13: 0 | Q13: 0 | R13: 0 | S13: 0 | T13: 0 | U13: 0 | V13: 0 | W13: 0 | X13: 0 | Y13: 0 | Z13: 6 | AA13: 0 | AB13: 0 | AC13: 0 | AD13: 0 | AE13: 0 | AF13: 0 | AG13: 0 | AH13: 0 | AI13: 0 | AJ13: 0 | AK13: 0 | AL13: 0 | AM13: 0 | AN13: 0 | AO13: 0 | AP13: 0 | AQ13: 0 | AR13: 0 | AS13: 0 | AT13: 0 | AU13: 0 | AV13: 0 | AW13: 0 | AX13: 0 | AY13: 0 | AZ13: 0 | BA13: 0 | BB13: 0 | BC13: 0 | BD13: 0 | BE13: 0 | BF13: 0 | BG13: 0 | BH13: 0 | BI13: 0 | BJ13: 0 | BK13: 0 | BL13: 0 | BM13: 0 | BN13: 0 | BO13: 0 | BP13: 0 | BQ13: 0 | BR13: 0 | BS13: 0 | BT13: 0 | BU13: 0 | BV13: 0 | BW13: 0 | BX13: 0 | BY13: 0 | BZ13: 0 | CA13: 0 | CB13: 0 | CC13: 0 | CD13: 0 | CE13: 0 | CF13: 0 | CG13: 0 | CH13: 11 | CI13: 0 | CJ13: 0 | CK13: 0 | CL13: 0 | CM13: 0 | CN13: 0 | CO13: 0 | CP13: 0 | CQ13: 0 | CR13: 0 | CS13: 0 | CT13: 0 | CU13: 0 | CV13: 0 | CW13: 0 | CX13: 0 | CY13: 0 | CZ13: 0 | DA13: 0 | DB13: 0 | DC13: 0 | DD13: 0 | DE13: 0 | DF13: 0 | DG13: 0 | DH13: 0 | DI13: 0 | DJ13: 0 | DK13: 0 | DL13: 0 | DM13: 0 | DN13: 0 | DO13: 0 | DP13: 0 | DQ13: 0 | DR13: 0 | DS13: 0 | DT13: 0 | DU13: 0 | DV13: 0 | DW13: 0 | DX13: 0 | DY13: 0 | DZ13: 0 | EA13: 0 | EB13: 0 | EC13: 0 | ED13: 0 | EE13: 0 | EF13: 0 | EG13: 0 | EH13: 0 | EI13: 0 | EJ13: 0 | EK13: 0 | EL13: 0 | EM13: 0 | EN13: 0 | EO13: 0 | EP13: 0 | EQ13: 0 | ER13: 0 | ES13: 0 | ET13: 0 | EU13: 13 | EV13: 0 | EW13: 0 | EX13: 0 | EY13: 0 | EZ13: 0 | FA13: 0 | FB13: 0 | FC13: 0 | FD13: 0 | FE13: 0 | FF13: 0 | FG13: 0 | FH13: 124 | FI13: 0 | FJ13: 0 | FK13: 0 | FL13: 0 | FM13: 0 | FN13: 0 | FO13: 0 | FP13: 0 | FQ13: 1 | FR13: 0 | FS13: 0 | FT13: 0 | FU13: 0 | FV13: 0 | FW13: 0 | FX13: 0 | FY13: 0 | FZ13: 0 | GA13: 0 | GB13: 0 | GC13: 0 | GD13: 0 | GE13: 1 | GF13: 0 | GG13: 0 | GH13: 0 | GI13: 0 | GJ13: 0 | GK13: 0 | GL13: 0 | GM13: 0 | GN13: 0 | GO13: 0 | GP13: 0 | GQ13: 0 | GR13: 0
A14: =A13+1 -> 46034 | B14: =TEXT(A14,"DDD") -> Mon | C14: =SUM(D14:GV14) -> 2864 | D14: 0 | E14: 29 | F14: 0 | G14: 0 | H14: 0 | I14: 0 | J14: 0 | K14: 0 | L14: 0 | M14: 0 | N14: 30 | O14: 65 | P14: 0 | Q14: 0 | R14: 0 | S14: 55 | T14: 128 | U14: 28 | V14: 0 | W14: 0 | X14: 0 | Y14: 0 | Z14: 74 | AA14: 0 | AB14: 0 | AC14: 0 | AD14: 74 | AE14: 0 | AF14: 0 | AG14: 0 | AH14: 0 | AI14: 0 | AJ14: 0 | AK14: 23 | AL14: 0 | AM14: 0 | AN14: 0 | AO14: 0 | AP14: 0 | AQ14: 0 | AR14: 0 | AS14: 0 | AT14: 0 | AU14: 0 | AV14: 0 | AW14: 45 | AX14: 59 | AY14: 0 | AZ14: 0 | BA14: 94 | BB14: 0 | BC14: 0 | BD14: 89 | BE14: 33 | BF14: 0 | BG14: 0 | BH14: 17 | BI14: 44 | BJ14: 0 | BK14: 0 | BL14: 0 | BM14: 0 | BN14: 0 | BO14: 0 | BP14: 0 | BQ14: 0 | BR14: 0 | BS14: 30 | BT14: 0 | BU14: 0 | BV14: 0 | BW14: 0 | BX14: 0 | BY14: 0 | BZ14: 0 | CA14: 0 | CB14: 0 | CC14: 29 | CD14: 192 | CE14: 0 | CF14: 18 | CG14: 0 | CH14: 56 | CI14: 0 | CJ14: 0 | CK14: 0 | CL14: 0 | CM14: 0 | CN14: 54 | CO14: 0 | CP14: 0 | CQ14: 0 | CR14: 0 | CS14: 20 | CT14: 23 | CU14: 0 | CV14: 0 | CW14: 0 | CX14: 0 | CY14: 0 | CZ14: 11 | DA14: 52 | DB14: 0 | DC14: 0 | DD14: 74 | DE14: 0 | DF14: 0 | DG14: 0 | DH14: 0 | DI14: 0 | DJ14: 0 | DK14: 0 | DL14: 19 | DM14: 0 | DN14: 67 | DO14: 21 | DP14: 0 | DQ14: 0 | DR14: 0 | DS14: 30 | DT14: 0 | DU14: 33 | DV14: 0 | DW14: 0 | DX14: 45 | DY14: 78 | DZ14: 0 | EA14: 0 | EB14: 50 | EC14: 0 | ED14: 0 | EE14: 0 | EF14: 0 | EG14: 0 | EH14: 12 | EI14: 0 | EJ14: 40 | EK14: 38 | EL14: 0 | EM14: 0 | EN14: 0 | EO14: 47 | EP14: 0 | EQ14: 0 | ER14: 10 | ES14: 0 | ET14: 0 | EU14: 43 | EV14: 57 | EW14: 15 | EX14: 34 | EY14: 46 | EZ14: 19 | FA14: 0 | FB14: 10 | FC14: 0 | FD14: 18 | FE14: 0 | FF14: 0 | FG14: 0 | FH14: 126 | FI14: 0 | FJ14: 0 | FK14: 0 | FL14: 0 | FM14: 0 | FN14: 0 | FO14: 49 | FP14: 0 | FQ14: 58 | FR14: 0 | FS14: 58 | FT14: 47 | FU14: 0 | FV14: 0 | FW14: 0 | FX14: 0 | FY14: 16 | FZ14: 49 | GA14: 0 | GB14: 0 | GC14: 0 | GD14: 0 | GE14: 45 | GF14: 64 | GG14: 0 | GH14: 0 | GI14: 0 | GJ14: 0 | GK14: 72 | GL14: 72 | GM14: 0 | GN14: 0 | GO14: 30 | GP14: 0 | GQ14: 0 | GR14: 0
A15: =A14+1 -> 46035 | B15: =TEXT(A15,"DDD") -> Tue | C15: =SUM(D15:GV15) -> 2308 | D15: 0 | E15: 6 | F15: 0 | G15: 0 | H15: 0 | I15: 0 | J15: 0 | K15: 0 | L15: 0 | M15: 0 | N15: 19 | O15: 64 | P15: 0 | Q15: 0 | R15: 0 | S15: 57 | T15: 118 | U15: 10 | V15: 0 | W15: 0 | X15: 0 | Y15: 0 | Z15: 72 | AA15: 0 | AB15: 0 | AC15: 0 | AD15: 78 | AE15: 0 | AF15: 0 | AG15: 0 | AH15: 0 | AI15: 0 | AJ15: 0 | AK15: 2 | AL15: 0 | AM15: 0 | AN15: 0 | AO15: 0 | AP15: 0 | AQ15: 0 | AR15: 0 | AS15: 0 | AT15: 0 | AU15: 0 | AV15: 0 | AW15: 33 | AX15: 56 | AY15: 0 | AZ15: 0 | BA15: 75 | BB15: 0 | BC15: 0 | BD15: 78 | BE15: 33 | BF15: 0 | BG15: 0 | BH15: 15 | BI15: 47 | BJ15: 0 | BK15: 0 | BL15: 0 | BM15: 0 | BN15: 0 | BO15: 0 | BP15: 0 | BQ15: 0 | BR15: 0 | BS15: 33 | BT15: 0 | BU15: 0 | BV15: 0 | BW15: 0 | BX15: 0 | BY15: 0 | BZ15: 0 | CA15: 0 | CB15: 0 | CC15: 0 | CD15: 36 | CE15: 0 | CF15: 2 | CG15: 0 | CH15: 53 | CI15: 0 | CJ15: 0 | CK15: 0 | CL15: 0 | CM15: 0 | CN15: 16 | CO15: 0 | CP15: 0 | CQ15: 0 | CR15: 0 | CS15: 9 | CT15: 24 | CU15: 0 | CV15: 0 | CW15: 0 | CX15: 0 | CY15: 10 | CZ15: 32 | DA15: 25 | DB15: 0 | DC15: 0 | DD15: 35 | DE15: 0 | DF15: 0 | DG15: 0 | DH15: 0 | DI15: 0 | DJ15: 0 | DK15: 0 | DL15: 11 | DM15: 0 | DN15: 52 | DO15: 21 | DP15: 0 | DQ15: 0 | DR15: 0 | DS15: 32 | DT15: 0 | DU15: 10 | DV15: 0 | DW15: 0 | DX15: 20 | DY15: 46 | DZ15: 48 | EA15: 0 | EB15: 30 | EC15: 0 | ED15: 0 | EE15: 0 | EF15: 0 | EG15: 0 | EH15: 0 | EI15: 0 | EJ15: 24 | EK15: 60 | EL15: 0 | EM15: 0 | EN15: 0 | EO15: 40 | EP15: 0 | EQ15: 0 | ER15: 0 | ES15: 0 | ET15: 0 | EU15: 36 | EV15: 92 | EW15: 26 | EX15: 29 | EY15: 41 | EZ15: 21 | FA15: 0 | FB15: 0 | FC15: 0 | FD15: 9 | FE15: 0 | FF15: 0 | FG15: 0 | FH15: 80 | FI15: 0 | FJ15: 0 | FK15: 0 | FL15: 0 | FM15: 0 | FN15: 0 | FO15: 49 | FP15: 0 | FQ15: 39 | FR15: 0 | FS15: 57 | FT15: 30 | FU15: 0 | FV15: 0 | FW15: 0 | FX15: 0 | FY15: 26 | FZ15: 29 | GA15: 0 | GB15: 0 | GC15: 0 | GD15: 0 | GE15: 78 | GF15: 36 | GG15: 0 | GH15: 0 | GI15: 0 | GJ15: 0 | GK15: 84 | GL15: 60 | GM15: 0 | GN15: 0 | GO15: 54 | GP15: 0 | GQ15: 0 | GR15: 0
... A33: =A32+1 -> 46053 | B33: =TEXT(A33,"DDD") -> Sat | C33: =SUM(D33:GV33) -> 3 | D33: 0 | E33: 0 | F33: 0 | G33: 0 | H33: 0 | I33: 0 | J33: 0 | K33: 0 | L33: 0 | M33: 0 | N33: 0 | O33: 0 | P33: 0 | Q33: 0 | R33: 0 | S33: 0 | T33: 0 | U33: 0 | V33: 0 | W33: 0 | X33: 0 | Y33: 0 | Z33: 0 | AA33: 0 | AB33: 0 | AC33: 0 | AD33: 0 | AE33: 0 | AF33: 0 | AG33: 0 | AH33: 0 | AI33: 0 | AJ33: 0 | AK33: 0 | AL33: 0 | AM33: 0 | AN33: 0 | AO33: 0 | AP33: 0 | AQ33: 0 | AR33: 0 | AS33: 0 | AT33: 0 | AU33: 0 | AV33: 0 | AW33: 0 | AX33: 0 | AY33: 0 | AZ33: 0 | BA33: 0 | BB33: 0 | BC33: 0 | BD33: 0 | BE33: 0 | BF33: 0 | BG33: 0 | BH33: 0 | BI33: 0 | BJ33: 0 | BK33: 0 | BL33: 0 | BM33: 0 | BN33: 0 | BO33: 0 | BP33: 0 | BQ33: 0 | BR33: 0 | BS33: 0 | BT33: 0 | BU33: 0 | BV33: 0 | BW33: 0 | BX33: 0 | BY33: 0 | BZ33: 0 | CA33: 0 | CB33: 0 | CC33: 0 | CD33: 0 | CE33: 0 | CF33: 0 | CG33: 0 | CH33: 0 | CI33: 0 | CJ33: 0 | CK33: 0 | CL33: 0 | CM33: 0 | CN33: 0 | CO33: 0 | CP33: 0 | CQ33: 0 | CR33: 0 | CS33: 0 | CT33: 0 | CU33: 0 | CV33: 0 | CW33: 0 | CX33: 0 | CY33: 0 | CZ33: 0 | DA33: 0 | DB33: 0 | DC33: 0 | DD33: 0 | DE33: 0 | DF33: 0 | DG33: 0 | DH33: 0 | DI33: 0 | DJ33: 0 | DK33: 0 | DL33: 0 | DM33: 0 | DN33: 3 | DO33: 0 | DP33: 0 | DQ33: 0 | DR33: 0 | DS33: 0 | DT33: 0 | DU33: 0 | DV33: 0 | DW33: 0 | DX33: 0 | DY33: 0 | DZ33: 0 | EA33: 0 | EB33: 0 | EC33: 0 | ED33: 0 | EE33: 0 | EF33: 0 | EG33: 0 | EH33: 0 | EI33: 0 | EJ33: 0 | EK33: 0 | EL33: 0 | EM33: 0 | EN33: 0 | EO33: 0 | EP33: 0 | EQ33: 0 | ER33: 0 | ES33: 0 | ET33: 0 | EU33: 0 | EV33: 0 | EW33: 0 | EX33: 0 | EY33: 0 | EZ33: 0 | FA33: 0 | FB33: 0 | FC33: 0 | FD33: 0 | FE33: 0 | FF33: 0 | FG33: 0 | FH33: 0 | FI33: 0 | FJ33: 0 | FK33: 0 | FL33: 0 | FM33: 0 | FN33: 0 | FO33: 0 | FP33: 0 | FQ33: 0 | FR33: 0 | FS33: 0 | FT33: 0 | FU33: 0 | FV33: 0 | FW33: 0 | FX33: 0 | FY33: 0 | FZ33: 0 | GA33: 0 | GB33: 0 | GC33: 0 | GD33: 0 | GE33: 0 | GF33: 0 | GG33: 0 | GH33: 0 | GI33: 0 | GJ33: 0 | GK33: 0 | GL33: 0 | GM33: 0 | GN33: 0 | GO33: 0 | GP33: 0 | GQ33: 0 | GR33: 0
A34: Grand Total | C34: =SUM(C3:C33) -> 55158 | D34: =SUM(D3:D33) -> 0 | E34: =SUM(E3:E33) -> 309 | F34: =SUM(F3:F33) -> 0 | G34: =SUM(G3:G33) -> 16 | H34: =SUM(H3:H33) -> 0 | I34: =SUM(I3:I33) -> 0 | J34: =SUM(J3:J33) -> 0 | ... GV34: =SUM(GV3:GV33) -> 0
C35: =C34+'Payroll MRO'!C34 -> 118326

Sheet Payroll MRO
A1: Date | B1: Day | C1: Overall | D1: Go To Index
D2: Aanya | E2: Ahila Sundaresan | F2: Alekhya Pokuri | G2: Ambar Romero | H2: Amel Yousfi | I2: Amrita Singh | J2: Andrea Lorenzano | K2: Angayarkanni Kannan | L2: Angel Edwards | M2: Anitaben Patel | N2: Anjali Devunuri | O2: Anjana Vijayan | P2: Ankana Biswas Dutta | Q2: Anshu Dubey | R2: Anusha Cheerla | S2: Anusha Kulageri | T2: Anusha Prasannakumar | U2: Arcelia Finkelberg | V2: Atchaya Rangasamy Venugopal | W2: Azumi Van Scyoc | X2: Babitha Koraganti | Y2: Balasubramani Kandasamy | Z2: Cecilia Hendricks | AA2: Chandana Bathina | AB2: Chandini Yellamilli | AC2: Chinmaya Jyothi Pulikallu | AD2: Damion Newell | AE2: Deepika Chintaluri | AF2: Devi Prakash | AG2: Devicharitha Malapati | AH2: Dhanalakshmi Nelluri | AI2: Dhivya Shankar | AJ2: Dhivyalakshmi Vigneshwaran | AK2: Diksha Vijaykumar More | AL2: Divya Babu | AM2: Divya Manjeshwar kamath | AN2: Divya Shree | AO2: Erianna Lockhart | AP2: Faith Ujjwala Singh | AQ2: Fallyan Redd | AR2: Farheen Hasham | AS2: Farzana Shaik | AT2: Fnu Supriya | AU2: Foua Yang | AV2: Franklin C Onyedili | AW2: Gayatri Paramsivam | AX2: Geetalakshmi Govinthara Annadhurai | AY2: Gia Erica Coleman | AZ2: Hadjer Ikram Yousfi | BA2: Haley VanNamee | BB2: Harathi Nuvuru | BC2: Hetal Shah | BD2: I-Asia Newkirk | BE2: Infanta Clara Victor Anthony | BF2: Jaya Singh | BG2: Jayashree Swain | BH2: Jhou Yang | BI2: Jyothi Venkatasubramanya | BJ2: Kabila Sivasankar | BK2: Kavya Krishnappa | BL2: Kawanna Brown | BM2: Komala Renuka Prasad | BN2: Krishnaveni | BO2: Krithika Balasubramaniam | BP2: Lakshmi Neelima Duddula | BQ2: LaSere Reid Smith | BR2: LATHA BUSIREDDY | BS2: Latrice Adams | BT2: Lavanya Vigrahala | BU2: Laxmi Sirisha Penumecha | BV2: Lipsa Padhy | BW2: Lokeswari Gummadi | BX2: Madhana Sundari Vijayarajan | BY2: Madhavi Balineni | BZ2: Madhura Alva | CA2: Madhuri Padala | CB2: Maira Becham | CC2: Manda Talwekar | CD2: Manjunath JagadishPai | CE2: Mariko Huskey | CF2: Marilyn Brown | CG2: Marina Ibrahim | CH2: Mathangi Radhakrishnan | CI2: Michelle Cox | CJ2: Minakshi Deepak | CK2: Mojisha Mohandas | CL2: Monalisa Roy | CM2: Mool Chand | CN2: Naagarashikaa Vijayakumar | CO2: Naganandhini Ganapathimaran | CP2: Namita Mishra | CQ2: Namrata Sharma | CR2: Namratha Koratala | CS2: Narmadhadevi Dharmapalan | CT2: Neena Mathew Saravanakumar | CU2: Neha Aaggarwal | CV2: Nilopher Lopes | CW2: Nitha Chathoth Kunhikrishnan | CX2: Padmapriya krishnamoorthy | CY2: Palak Porwal | CZ2: Pavithra Balaji | DA2: Pavithra Manas Panda | DB2: Pavitra Rani Allam | DC2: Pooja Solanki | DD2: Poongothai Duraisamy | DE2: Pragyan Paramita Mohanty | DF2: Pranusha Dontineni | DG2: Prasana Kotagiri | DH2: Prathima Krishnamurthy Yadav | DI2: Prathima Lakkireddy | DJ2: PRAVALLIKA NUTHALAPATI | DK2: Priti Suman | DL2: Priyadarsini Baral | DM2: Priyanka Chandrikapure | DN2: Priyanka Dey Sarkar | DO2: Priyanka Gadar | DP2: Pushpaja Vullamgunta | DQ2: Rajameenakshi Sankarasubramanian | DR2: Rajeshwari Thammineni | DS2: Ramsheena Nadathalakkel | DT2: Ramya Muralidharan | DU2: Ramya Sudarshan Palavalli | DV2: Randi Wood | DW2: Rashmi Gupta | DX2: Rashmi Kottachery | DY2: Rashmi Rangdale | DZ2: Rathika Jude | EA2: Ratnasree Gudla | EB2: Reejaramani Subramani | EC2: Reema Rasheed | ED2: Reshmi Pulickal Radhakrishnan | EE2: Rima Loganathan | EF2: Rishi Goswami | EG2: Roja Punna | EH2: Rupali Bangar | EI2: Rutuja Rajput | EJ2: Sabiha Khan | EK2: Sai Santhya Ravikumar | EL2: Sangeetha Jeyabalan | EM2: Sanjana Mandal | EN2: Sara Abdelsayed | EO2: Saranya Sabarish | EP2: Sasikala Murugesan | EQ2: Sathya Ezhilan | ER2: Sathya Naveenraj | ES2: Selvakamatchi Rajamani | ET2: Shagida Nishwan | EU2: Sharanya Madhavan | EV2: Sharmila Lakshmipathy | EW2: Sharmila Raghavan | EX2: Siddhardha Yalavarthy | EY2: Sindhu Selvaraj | EZ2: Sindhu Thanigesan | FA2: Sireesha Gottimukkala | FB2: Snehal Choudhari | FC2: Snighdha Dave | FD2: Somdutta Paul | FE2: Sonali Gupta | FF2: Sonia Mohanty | FG2: Soumya kalyanaraman | FH2: Sowjanya Ravella | FI2: Sree Nalini Uduta | FJ2: Sreedevi Salapu | FK2: Srikanya R | FL2: Srilekha Kotte | FM2: Sripriyadarshini | FN2: Srividhyalakshmi Murugadass | FO2: Sruthi Arambachalil | FP2: Subasri Swaminathan | FQ2: Subhanandhini Kumarasamy | FR2: Subhina Bhaskar | FS2: subratha suresh kamat | FT2: Suchitra Rajesh | FU2: Sudesh Goel | FV2: Sunitha nara | FW2: Swathi Kodali | FX2: SWATHI LAKSHMI GUNDURU | FY2: Swati bartake | FZ2: Swati Ghogare | GA2: Sweety Ranka | GB2: Tapasi Rath | GC2: Tarshik Spurling | GD2: Tej Patel | GE2: Umamaheswari Shanmugam | GF2: Usha Devi Singaravelu | GG2: Vaishnavi Devi Bunja Dhinakaran | GH2: Valarmathi Magudeswaran | GI2: Valliammai Ramanathan | GJ2: Vani Hanumantu | GK2: Varsha Javali | GL2: Vasuda Rawal | GM2: Vasudha Kodi | GN2: Venkata Vemuri | GO2: Vidya Thirunavukkarasu | GP2: Vijayalakshmi Bhaskaran | GQ2: Vyom Bhandari | GR2: Yazhini Ravichandran
A3: 46023 | B3: =TEXT(A3,"DDD") -> Thu | C3: =SUM(D3:GV3) -> 739 | D3: 0 | E3: 0 | F3: 0 | G3: 0 | H3: 0 | I3: 0 | J3: 0 | K3: 0 | L3: 0 | M3: 0 | N3: 0 | O3: 0 | P3: 0 | Q3: 0 | R3: 0 | S3: 0 | T3: 0 | U3: 0 | V3: 0 | W3: 4 | X3: 0 | Y3: 32 | Z3: 0 | AA3: 0 | AB3: 10 | AC3: 0 | AD3: 0 | AE3: 0 | AF3: 0 | AG3: 51 | AH3: 0 | AI3: 0 | AJ3: 0 | AK3: 0 | AL3: 0 | AM3: 0 | AN3: 0 | AO3: 0 | AP3: 0 | AQ3: 0 | AR3: 0 | AS3: 0 | AT3: 0 | AU3: 0 | AV3: 0 | AW3: 0 | AX3: 0 | AY3: 0 | AZ3: 0 | BA3: 0 | BB3: 0 | BC3: 0 | BD3: 0 | BE3: 0 | BF3: 0 | BG3: 17 | BH3: 0 | BI3: 0 | BJ3: 0 | BK3: 0 | BL3: 0 | BM3: 0 | BN3: 0 | BO3: 0 | BP3: 0 | BQ3: 0 | BR3: 0 | BS3: 0 | BT3: 0 | BU3: 0 | BV3: 0 | BW3: 0 | BX3: 19 | BY3: 0 | BZ3: 0 | CA3: 0 | CB3: 0 | CC3: 0 | CD3: 27 | CE3: 0 | CF3: 0 | CG3: 0 | CH3: 0 | CI3: 0 | CJ3: 30 | CK3: 0 | CL3: 0 | CM3: 0 | CN3: 0 | CO3: 0 | CP3: 0 | CQ3: 0 | CR3: 0 | CS3: 0 | CT3: 0 | CU3: 89 | CV3: 0 | CW3: 0 | CX3: 0 | CY3: 0 | CZ3: 0 | DA3: 0 | DB3: 0 | DC3: 0 | DD3: 0 | DE3: 0 | DF3: 0 | DG3: 0 | DH3: 0 | DI3: 0 | DJ3: 0 | DK3: 83 | DL3: 0 | DM3: 0 | DN3: 0 | DO3: 0 | DP3: 48 | DQ3: 0 | DR3: 0 | DS3: 0 | DT3: 0 | DU3: 0 | DV3: 0 | DW3: 0 | DX3: 0 | DY3: 0 | DZ3: 0 | EA3: 0 | EB3: 0 | EC3: 22 | ED3: 17 | EE3: 12 | EF3: 0 | EG3: 0 | EH3: 0 | EI3: 109 | EJ3: 0 | EK3: 0 | EL3: 0 | EM3: 0 | EN3: 0 | EO3: 0 | EP3: 0 | EQ3: 0 | ER3: 0 | ES3: 0 | ET3: 0 | EU3: 0 | EV3: 0 | EW3: 0 | EX3: 0 | EY3: 0 | EZ3: 0 | FA3: 0 | FB3: 0 | FC3: 0 | FD3: 0 | FE3: 25 | FF3: 14 | FG3: 0 | FH3: 0 | FI3: 0 | FJ3: 0 | FK3: 3 | FL3: 0 | FM3: 0 | FN3: 0 | FO3: 0 | FP3: 0 | FQ3: 0 | FR3: 0 | FS3: 0 | FT3: 0 | FU3: 0 | FV3: 0 | FW3: 0 | FX3: 0 | FY3: 0 | FZ3: 0 | GA3: 0 | GB3: 0 | GC3: 0 | GD3: 122 | GE3: 0 | GF3: 0 | GG3: 4 | GH3: 0 | GI3: 0 | GJ3: 1 | GK3: 0 | GL3: 0 | GM3: 0 | GN3: 0 | GO3: 0 | GP3: 0 | GQ3: 0 | GR3: 0
A4: =A3+1 -> 46024 | B4: =TEXT(A4,"DDD") -> Fri | C4: =SUM(D4:GV4) -> 2285 | D4: 0 | E4: 0 | F4: 0 | G4: 0 | H4: 33 | I4: 0 | J4: 0 | K4: 0 | L4: 0 | M4: 0 | N4: 0 | O4: 0 | P4: 26 | Q4: 0 | R4: 162 | S4: 0 | T4: 0 | U4: 0 | V4: 54 | W4: 25 | X4: 0 | Y4: 28 | Z4: 0 | AA4: 12 | AB4: 6 | AC4: 0 | AD4: 0 | AE4: 0 | AF4: 0 | AG4: 0 | AH4: 0 | AI4: 0 | AJ4: 0 | AK4: 0 | AL4: 0 | AM4: 0 | AN4: 0 | AO4: 0 | AP4: 14 | AQ4: 0 | AR4: 28 | AS4: 0 | AT4: 0 | AU4: 0 | AV4: 0 | AW4: 0 | AX4: 0 | AY4: 0 | AZ4: 0 | BA4: 0 | BB4: 0 | BC4: 0 | BD4: 0 | BE4: 0 | BF4: 0 | BG4: 29 | BH4: 0 | BI4: 0 | BJ4: 17 | BK4: 0 | BL4: 119 | BM4: 0 | BN4: 0 | BO4: 0 | BP4: 61 | BQ4: 0 | BR4: 0 | BS4: 0 | BT4: 0 | BU4: 20 | BV4: 35 | BW4: 40 | BX4: 66 | BY4: 0 | BZ4: 17 | CA4: 0 | CB4: 0 | CC4: 0 | CD4: 0 | CE4: 0 | CF4: 0 | CG4: 0 | CH4: 0 | CI4: 0 | CJ4: 105 | CK4: 0 | CL4: 0 | CM4: 0 | CN4: 0 | CO4: 0 | CP4: 0 | CQ4: 0 | CR4: 0 | CS4: 0 | CT4: 0 | CU4: 0 | CV4: 0 | CW4: 0 | CX4: 0 | CY4: 46 | CZ4: 0 | DA4: 0 | DB4: 0 | DC4: 0 | DD4: 0 | DE4: 30 | DF4: 0 | DG4: 70 | DH4: 12 | DI4: 72 | DJ4: 0 | DK4: 147 | DL4: 0 | DM4: 0 | DN4: 0 | DO4: 0 | DP4: 80 | DQ4: 0 | DR4: 0 | DS4: 0 | DT4: 63 | DU4: 0 | DV4: 0 | DW4: 0 | DX4: 0 | DY4: 0 | DZ4: 0 | EA4: 0 | EB4: 0 | EC4: 12 | ED4: 94 | EE4: 15 | EF4: 0 | EG4: 0 | EH4: 0 | EI4: 0 | EJ4: 0 | EK4: 0 | EL4: 0 | EM4: 57 | EN4: 0 | EO4: 0 | EP4: 0 | EQ4: 25 | ER4: 0 | ES4: 0 | ET4: 65 | EU4: 0 | EV4: 0 | EW4: 0 | EX4: 0 | EY4: 0 | EZ4: 0 | FA4: 0 | FB4: 0 | FC4: 0 | FD4: 0 | FE4: 26 | FF4: 41 | FG4: 0 | FH4: 0 | FI4: 0 | FJ4: 0 | FK4: 20 | FL4: 0 | FM4: 0 | FN4: 31 | FO4: 0 | FP4: 61 | FQ4: 0 | FR4: 0 | FS4: 0 | FT4: 0 | FU4: 0 | FV4: 0 | FW4: 0 | FX4: 0 | FY4: 0 | FZ4: 0 | GA4: 0 | GB4: 0 | GC4: 0 | GD4: 0 | GE4: 0 | GF4: 0 | GG4: 111 | GH4: 13 | GI4: 0 | GJ4: 86 | GK4: 0 | GL4: 0 | GM4: 115 | GN4: 0 | GO4: 0 | GP4: 41 | GQ4: 0 | GR4: 55
A5: =A4+1 -> 46025 | B5: =TEXT(A5,"DDD") -> Sat | C5: =SUM(D5:GV5) -> 762 | D5: 0 | E5: 0 | F5: 0 | G5: 0 | H5: 11 | I5: 0 | J5: 0 | K5: 0 | L5: 0 | M5: 0 | N5: 0 | O5: 0 | P5: 0 | Q5: 0 | R5: 0 | S5: 0 | T5: 0 | U5: 0 | V5: 0 | W5: 0 | X5: 0 | Y5: 42 | Z5: 0 | AA5: 0 | AB5: 0 | AC5: 0 | AD5: 0 | AE5: 0 | AF5: 0 | AG5: 0 | AH5: 0 | AI5: 0 | AJ5: 0 | AK5: 0 | AL5: 0 | AM5: 0 | AN5: 0 | AO5: 0 | AP5: 0 | AQ5: 0 | AR5: 0 | AS5: 0 | AT5: 0 | AU5: 0 | AV5: 0 | AW5: 0 | AX5: 0 | AY5: 0 | AZ5: 0 | BA5: 0 | BB5: 0 | BC5: 0 | BD5: 0 | BE5: 0 | BF5: 0 | BG5: 0 | BH5: 0 | BI5: 0 | BJ5: 0 | BK5: 0 | BL5: 0 | BM5: 0 | BN5: 0 | BO5: 0 | BP5: 0 | BQ5: 0 | BR5: 0 | BS5: 0 | BT5: 0 | BU5: 0 | BV5: 0 | BW5: 0 | BX5: 0 | BY5: 0 | BZ5: 0 | CA5: 0 | CB5: 0 | CC5: 0 | CD5: 0 | CE5: 0 | CF5: 0 | CG5: 0 | CH5: 0 | CI5: 0 | CJ5: 0 | CK5: 0 | CL5: 24 | CM5: 0 | CN5: 0 | CO5: 0 | CP5: 0 | CQ5: 0 | CR5: 0 | CS5: 0 | CT5: 0 | CU5: 252 | CV5: 0 | CW5: 0 | CX5: 0 | CY5: 0 | CZ5: 0 | DA5: 0 | DB5: 0 | DC5: 0 | DD5: 0 | DE5: 0 | DF5: 0 | DG5: 0 | DH5: 0 | DI5: 0 | DJ5: 0 | DK5: 192 | DL5: 0 | DM5: 0 | DN5: 0 | DO5: 0 | DP5: 37 | DQ5: 0 | DR5: 0 | DS5: 0 | DT5: 0 | DU5: 0 | DV5: 0 | DW5: 0 | DX5: 0 | DY5: 0 | DZ5: 0 | EA5: 0 | EB5: 0 | EC5: 0 | ED5: 17 | EE5: 0 | EF5: 0 | EG5: 0 | EH5: 0 | EI5: 0 | EJ5: 0 | EK5: 0 | EL5: 0 | EM5: 0 | EN5: 0 | EO5: 0 | EP5: 0 | EQ5: 0 | ER5: 0 | ES5: 0 | ET5: 0 | EU5: 0 | EV5: 0 | EW5: 0 | EX5: 0 | EY5: 0 | EZ5: 0 | FA5: 0 | FB5: 0 | FC5: 0 | FD5: 0 | FE5: 31 | FF5: 22 | FG5: 0 | FH5: 0 | FI5: 0 | FJ5: 0 | FK5: 0 | FL5: 0 | FM5: 0 | FN5: 0 | FO5: 0 | FP5: 0 | FQ5: 0 | FR5: 0 | FS5: 0 | FT5: 0 | FU5: 0 | FV5: 0 | FW5: 0 | FX5: 0 | FY5: 0 | FZ5: 0 | GA5: 0 | GB5: 0 | GC5: 0 | GD5: 0 | GE5: 0 | GF5: 0 | GG5: 14 | GH5: 0 | GI5: 0 | GJ5: 59 | GK5: 0 | GL5: 0 | GM5: 61 | GN5: 0 | GO5: 0 | GP5: 0 | GQ5: 0 | GR5: 0
A6: =A5+1 -> 46026 | B6: =TEXT(A6,"DDD") -> Sun | C6: =SUM(D6:GV6) -> 653 | D6: 0 | E6: 0 | F6: 0 | G6: 0 | H6: 10 | I6: 0 | J6: 0 | K6: 0 | L6: 0 | M6: 0 | N6: 0 | O6: 0 | P6: 17 | Q6: 0 | R6: 0 | S6: 0 | T6: 0 | U6: 0 | V6: 0 | W6: 0 | X6: 0 | Y6: 49 | Z6: 0 | AA6: 0 | AB6: 0 | AC6: 0 | AD6: 0 | AE6: 0 | AF6: 0 | AG6: 0 | AH6: 0 | AI6: 0 | AJ6: 0 | AK6: 0 | AL6: 0 | AM6: 0 | AN6: 0 | AO6: 0 | AP6: 0 | AQ6: 0 | AR6: 0 | AS6: 0 | AT6: 0 | AU6: 0 | AV6: 0 | AW6: 0 | AX6: 0 | AY6: 0 | AZ6: 0 | BA6: 0 | BB6: 0 | BC6: 0 | BD6: 0 | BE6: 0 | BF6: 0 | BG6: 0 | BH6: 0 | BI6: 0 | BJ6: 0 | BK6: 0 | BL6: 0 | BM6: 0 | BN6: 0 | BO6: 0 | BP6: 0 | BQ6: 0 | BR6: 0 | BS6: 0 | BT6: 0 | BU6: 0 | BV6: 0 | BW6: 0 | BX6: 0 | BY6: 0 | BZ6: 59 | CA6: 0 | CB6: 0 | CC6: 0 | CD6: 0 | CE6: 0 | CF6: 0 | CG6: 0 | CH6: 0 | CI6: 0 | CJ6: 0 | CK6: 0 | CL6: 0 | CM6: 0 | CN6: 0 | CO6: 0 | CP6: 0 | CQ6: 0 | CR6: 0 | CS6: 0 | CT6: 0 | CU6: 0 | CV6: 0 | CW6: 0 | CX6: 0 | CY6: 72 | CZ6: 0 | DA6: 0 | DB6: 0 | DC6: 0 | DD6: 0 | DE6: 70 | DF6: 0 | DG6: 1 | DH6: 0 | DI6: 0 | DJ6: 0 | DK6: 114 | DL6: 0 | DM6: 0 | DN6: 0 | DO6: 0 | DP6: 0 | DQ6: 0 | DR6: 0 | DS6: 0 | DT6: 0 | DU6: 0 | DV6: 0 | DW6: 0 | DX6: 0 | DY6: 0 | DZ6: 0 | EA6: 0 | EB6: 0 | EC6: 0 | ED6: 0 | EE6: 0 | EF6: 0 | EG6: 0 | EH6: 0 | EI6: 0 | EJ6: 0 | EK6: 0 | EL6: 0 | EM6: 0 | EN6: 0 | EO6: 0 | EP6: 0 | EQ6: 0 | ER6: 0 | ES6: 0 | ET6: 0 | EU6: 0 | EV6: 0 | EW6: 0 | EX6: 0 | EY6: 0 | EZ6: 0 | FA6: 0 | FB6: 0 | FC6: 0 | FD6: 0 | FE6: 0 | FF6: 20 | FG6: 0 | FH6: 0 | FI6: 0 | FJ6: 0 | FK6: 19 | FL6: 0 | FM6: 0 | FN6: 0 | FO6: 0 | FP6: 24 | FQ6: 0 | FR6: 0 | FS6: 0 | FT6: 0 | FU6: 0 | FV6: 0 | FW6: 0 | FX6: 0 | FY6: 0 | FZ6: 0 | GA6: 0 | GB6: 0 | GC6: 0 | GD6: 0 | GE6: 0 | GF6: 0 | GG6: 19 | GH6: 0 | GI6: 0 | GJ6: 19 | GK6: 0 | GL6: 0 | GM6: 97 | GN6: 11 | GO6: 0 | GP6: 48 | GQ6: 0 | GR6: 4
A7: =A6+1 -> 46027 | B7: =TEXT(A7,"DDD") -> Mon | C7: =SUM(D7:GV7) -> 2949 | D7: 0 | E7: 0 | F7: 0 | G7: 0 | H7: 41 | I7: 47 | J7: 0 | K7: 0 | L7: 0 | M7: 0 | N7: 0 | O7: 0 | P7: 44 | Q7: 37 | R7: 113 | S7: 0 | T7: 0 | U7: 0 | V7: 35 | W7: 45 | X7: 0 | Y7: 61 | Z7: 0 | AA7: 32 | AB7: 9 | AC7: 0 | AD7: 0 | AE7: 0 | AF7: 0 | AG7: 50 | AH7: 0 | AI7: 0 | AJ7: 0 | AK7: 0 | AL7: 0 | AM7: 0 | AN7: 3 | AO7: 0 | AP7: 21 | AQ7: 15 | AR7: 1 | AS7: 0 | AT7: 0 | AU7: 0 | AV7: 0 | AW7: 0 | AX7: 0 | AY7: 0 | AZ7: 22 | BA7: 0 | BB7: 43 | BC7: 0 | BD7: 0 | BE7: 0 | BF7: 0 | BG7: 25 | BH7: 0 | BI7: 0 | BJ7: 15 | BK7: 0 | BL7: 40 | BM7: 0 | BN7: 0 | BO7: 30 | BP7: 50 | BQ7: 0 | BR7: 0 | BS7: 0 | BT7: 0 | BU7: 42 | BV7: 1 | BW7: 25 | BX7: 0 | BY7: 0 | BZ7: 171 | CA7: 66 | CB7: 0 | CC7: 0 | CD7: 0 | CE7: 0 | CF7: 0 | CG7: 0 | CH7: 0 | CI7: 0 | CJ7: 108 | CK7: 0 | CL7: 48 | CM7: 0 | CN7: 0 | CO7: 0 | CP7: 0 | CQ7: 0 | CR7: 0 | CS7: 0 | CT7: 0 | CU7: 92 | CV7: 0 | CW7: 0 | CX7: 0 | CY7: 113 | CZ7: 0 | DA7: 0 | DB7: 0 | DC7: 0 | DD7: 0 | DE7: 0 | DF7: 0 | DG7: 25 | DH7: 13 | DI7: 80 | DJ7: 0 | DK7: 130 | DL7: 0 | DM7: 0 | DN7: 0 | DO7: 0 | DP7: 0 | DQ7: 48 | DR7: 78 | DS7: 0 | DT7: 75 | DU7: 0 | DV7: 0 | DW7: 0 | DX7: 0 | DY7: 0 | DZ7: 0 | EA7: 0 | EB7: 0 | EC7: 5 | ED7: 99 | EE7: 0 | EF7: 54 | EG7: 0 | EH7: 0 | EI7: 93 | EJ7: 0 | EK7: 0 | EL7: 42 | EM7: 30 | EN7: 0 | EO7: 0 | EP7: 37 | EQ7: 0 | ER7: 0 | ES7: 0 | ET7: 72 | EU7: 0 | EV7: 0 | EW7: 0 | EX7: 0 | EY7: 0 | EZ7: 0 | FA7: 0 | FB7: 0 | FC7: 0 | FD7: 0 | FE7: 28 | FF7: 50 | FG7: 0 | FH7: 0 | FI7: 1 | FJ7: 0 | FK7: 20 | FL7: 0 | FM7: 0 | FN7: 0 | FO7: 0 | FP7: 47 | FQ7: 0 | FR7: 0 | FS7: 0 | FT7: 0 | FU7: 0 | FV7: 0 | FW7: 0 | FX7: 0 | FY7: 0 | FZ7: 0 | GA7: 0 | GB7: 55 | GC7: 0 | GD7: 97 | GE7: 0 | GF7: 0 | GG7: 62 | GH7: 15 | GI7: 0 | GJ7: 48 | GK7: 0 | GL7: 0 | GM7: 76 | GN7: 43 | GO7: 0 | GP7: 41 | GQ7: 0 | GR7: 40
A8: =A7+1 -> 46028 | B8: =TEXT(A8,"DDD") -> Tue | C8: =SUM(D8:GV8) -> 2867 | D8: 0 | E8: 0 | F8: 0 | G8: 0 | H8: 14 | I8: 42 | J8: 0 | K8: 0 | L8: 0 | M8: 0 | N8: 0 | O8: 0 | P8: 40 | Q8: 25 | R8: 153 | S8: 0 | T8: 0 | U8: 0 | V8: 0 | W8: 0 | X8: 0 | Y8: 73 | Z8: 0 | AA8: 38 | AB8: 22 | AC8: 0 | AD8: 0 | AE8: 0 | AF8: 0 | AG8: 32 | AH8: 0 | AI8: 0 | AJ8: 0 | AK8: 0 | AL8: 0 | AM8: 0 | AN8: 8 | AO8: 0 | AP8: 18 | AQ8: 0 | AR8: 0 | AS8: 0 | AT8: 0 | AU8: 0 | AV8: 0 | AW8: 0 | AX8: 0 | AY8: 0 | AZ8: 11 | BA8: 0 | BB8: 67 | BC8: 0 | BD8: 0 | BE8: 0 | BF8: 0 | BG8: 41 | BH8: 0 | BI8: 0 | BJ8: 21 | BK8: 0 | BL8: 39 | BM8: 0 | BN8: 0 | BO8: 33 | BP8: 25 | BQ8: 0 | BR8: 0 | BS8: 0 | BT8: 0 | BU8: 120 | BV8: 27 | BW8: 62 | BX8: 0 | BY8: 0 | BZ8: 140 | CA8: 78 | CB8: 0 | CC8: 0 | CD8: 0 | CE8: 2 | CF8: 0 | CG8: 0 | CH8: 0 | CI8: 0 | CJ8: 110 | CK8: 0 | CL8: 65 | CM8: 0 | CN8: 0 | CO8: 0 | CP8: 0 | CQ8: 0 | CR8: 0 | CS8: 0 | CT8: 0 | CU8: 74 | CV8: 0 | CW8: 0 | CX8: 0 | CY8: 100 | CZ8: 0 | DA8: 0 | DB8: 0 | DC8: 0 | DD8: 0 | DE8: 0 | DF8: 0 | DG8: 87 | DH8: 16 | DI8: 51 | DJ8: 0 | DK8: 46 | DL8: 0 | DM8: 36 | DN8: 0 | DO8: 0 | DP8: 0 | DQ8: 18 | DR8: 71 | DS8: 0 | DT8: 43 | DU8: 0 | DV8: 0 | DW8: 0 | DX8: 0 | DY8: 0 | DZ8: 39 | EA8: 0 | EB8: 0 | EC8: 0 | ED8: 87 | EE8: 0 | EF8: 0 | EG8: 0 | EH8: 0 | EI8: 84 | EJ8: 0 | EK8: 0 | EL8: 85 | EM8: 25 | EN8: 0 | EO8: 0 | EP8: 40 | EQ8: 6 | ER8: 0 | ES8: 0 | ET8: 5 | EU8: 0 | EV8: 0 | EW8: 0 | EX8: 0 | EY8: 0 | EZ8: 0 | FA8: 0 | FB8: 0 | FC8: 0 | FD8: 0 | FE8: 0 | FF8: 48 | FG8: 0 | FH8: 0 | FI8: 0 | FJ8: 0 | FK8: 46 | FL8: 0 | FM8: 15 | FN8: 76 | FO8: 0 | FP8: 25 | FQ8: 0 | FR8: 0 | FS8: 0 | FT8: 0 | FU8: 0 | FV8: 0 | FW8: 0 | FX8: 0 | FY8: 0 | FZ8: 0 | GA8: 0 | GB8: 34 | GC8: 0 | GD8: 0 | GE8: 0 | GF8: 0 | GG8: 87 | GH8: 10 | GI8: 0 | GJ8: 76 | GK8: 0 | GL8: 0 | GM8: 135 | GN8: 42 | GO8: 0 | GP8: 22 | GQ8: 0 | GR8: 32
A9: =A8+1 -> 46029 | B9: =TEXT(A9,"DDD") -> Wed | C9: =SUM(D9:GV9) -> 2897 | D9: 0 | E9: 64 | F9: 0 | G9: 0 | H9: 33 | I9: 66 | J9: 0 | K9: 0 | L9: 0 | M9: 0 | N9: 0 | O9: 0 | P9: 43 | Q9: 25 | R9: 121 | S9: 0 | T9: 0 | U9: 0 | V9: 0 | W9: 0 | X9: 0 | Y9: 65 | Z9: 0 | AA9: 0 | AB9: 34 | AC9: 0 | AD9: 0 | AE9: 0 | AF9: 0 | AG9: 20 | AH9: 0 | AI9: 0 | AJ9: 0 | AK9: 0 | AL9: 0 | AM9: 0 | AN9: 18 | AO9: 0 | AP9: 7 | AQ9: 0 | AR9: 32 | AS9: 0 | AT9: 0 | AU9: 0 | AV9: 0 | AW9: 0 | AX9: 0 | AY9: 0 | AZ9: 17 | BA9: 0 | BB9: 102 | BC9: 0 | BD9: 0 | BE9: 0 | BF9: 0 | BG9: 44 | BH9: 0 | BI9: 0 | BJ9: 1 | BK9: 0 | BL9: 41 | BM9: 0 | BN9: 0 | BO9: 35 | BP9: 20 | BQ9: 0 | BR9: 0 | BS9: 0 | BT9: 0 | BU9: 20 | BV9: 12 | BW9: 58 | BX9: 64 | BY9: 0 | BZ9: 80 | CA9: 34 | CB9: 53 | CC9: 0 | CD9: 0 | CE9: 0 | CF9: 0 | CG9: 0 | CH9: 0 | CI9: 0 | CJ9: 147 | CK9: 0 | CL9: 58 | CM9: 0 | CN9: 0 | CO9: 0 | CP9: 0 | CQ9: 0 | CR9: 0 | CS9: 0 | CT9: 0 | CU9: 0 | CV9: 0 | CW9: 0 | CX9: 0 | CY9: 87 | CZ9: 0 | DA9: 0 | DB9: 0 | DC9: 0 | DD9: 0 | DE9: 0 | DF9: 0 | DG9: 23 | DH9: 15 | DI9: 94 | DJ9: 0 | DK9: 53 | DL9: 0 | DM9: 0 | DN9: 0 | DO9: 0 | DP9: 0 | DQ9: 51 | DR9: 60 | DS9: 0 | DT9: 62 | DU9: 0 | DV9: 0 | DW9: 0 | DX9: 0 | DY9: 0 | DZ9: 65 | EA9: 0 | EB9: 0 | EC9: 0 | ED9: 84 | EE9: 0 | EF9: 82 | EG9: 0 | EH9: 0 | EI9: 87 | EJ9: 0 | EK9: 0 | EL9: 67 | EM9: 32 | EN9: 0 | EO9: 0 | EP9: 19 | EQ9: 29 | ER9: 0 | ES9: 0 | ET9: 46 | EU9: 0 | EV9: 0 | EW9: 0 | EX9: 0 | EY9: 0 | EZ9: 0 | FA9: 0 | FB9: 0 | FC9: 0 | FD9: 0 | FE9: 0 | FF9: 35 | FG9: 0 | FH9: 0 | FI9: 1 | FJ9: 0 | FK9: 24 | FL9: 0 | FM9: 0 | FN9: 19 | FO9: 0 | FP9: 34 | FQ9: 0 | FR9: 0 | FS9: 0 | FT9: 0 | FU9: 0 | FV9: 0 | FW9: 0 | FX9: 0 | FY9: 0 | FZ9: 0 | GA9: 0 | GB9: 57 | GC9: 0 | GD9: 60 | GE9: 0 | GF9: 0 | GG9: 63 | GH9: 10 | GI9: 0 | GJ9: 71 | GK9: 0 | GL9: 0 | GM9: 137 | GN9: 37 | GO9: 0 | GP9: 50 | GQ9: 0 | GR9: 29
A10: =A9+1 -> 46030 | B10: =TEXT(A10,"DDD") -> Thu | C10: =SUM(D10:GV10) -> 3753 | D10: 0 | E10: 10 | F10: 0 | G10: 0 | H10: 35 | I10: 62 | J10: 0 | K10: 0 | L10: 0 | M10: 0 | N10: 0 | O10: 0 | P10: 32 | Q10: 38 | R10: 116 | S10: 0 | T10: 0 | U10: 0 | V10: 36 | W10: 0 | X10: 0 | Y10: 65 | Z10: 0 | AA10: 20 | AB10: 26 | AC10: 0 | AD10: 0 | AE10: 0 | AF10: 0 | AG10: 43 | AH10: 0 | AI10: 0 | AJ10: 0 | AK10: 0 | AL10: 0 | AM10: 0 | AN10: 14 | AO10: 0 | AP10: 15 | AQ10: 0 | AR10: 0 | AS10: 0 | AT10: 0 | AU10: 0 | AV10: 0 | AW10: 0 | AX10: 0 | AY10: 0 | AZ10: 52 | BA10: 0 | BB10: 98 | BC10: 0 | BD10: 0 | BE10: 0 | BF10: 0 | BG10: 40 | BH10: 0 | BI10: 0 | BJ10: 0 | BK10: 0 | BL10: 81 | BM10: 0 | BN10: 0 | BO10: 33 | BP10: 35 | BQ10: 0 | BR10: 0 | BS10: 0 | BT10: 0 | BU10: 50 | BV10: 14 | BW10: 41 | BX10: 172 | BY10: 0 | BZ10: 91 | CA10: 62 | CB10: 75 | CC10: 0 | CD10: 77 | CE10: 60 | CF10: 0 | CG10: 0 | CH10: 0 | CI10: 0 | CJ10: 180 | CK10: 0 | CL10: 55 | CM10: 0 | CN10: 0 | CO10: 0 | CP10: 0 | CQ10: 0 | CR10: 0 | CS10: 0 | CT10: 0 | CU10: 50 | CV10: 0 | CW10: 0 | CX10: 0 | CY10: 100 | CZ10: 0 | DA10: 0 | DB10: 0 | DC10: 0 | DD10: 0 | DE10: 0 | DF10: 0 | DG10: 12 | DH10: 18 | DI10: 107 | DJ10: 0 | DK10: 202 | DL10: 0 | DM10: 0 | DN10: 0 | DO10: 0 | DP10: 0 | DQ10: 46 | DR10: 68 | DS10: 0 | DT10: 51 | DU10: 0 | DV10: 0 | DW10: 0 | DX10: 0 | DY10: 0 | DZ10: 172 | EA10: 0 | EB10: 0 | EC10: 0 | ED10: 111 | EE10: 0 | EF10: 84 | EG10: 0 | EH10: 0 | EI10: 84 | EJ10: 0 | EK10: 0 | EL10: 74 | EM10: 64 | EN10: 0 | EO10: 0 | EP10: 32 | EQ10: 22 | ER10: 0 | ES10: 0 | ET10: 39 | EU10: 0 | EV10: 0 | EW10: 0 | EX10: 0 | EY10: 0 | EZ10: 0 | FA10: 0 | FB10: 0 | FC10: 0 | FD10: 0 | FE10: 0 | FF10: 20 | FG10: 0 | FH10: 0 | FI10: 22 | FJ10: 0 | FK10: 19 | FL10: 0 | FM10: 0 | FN10: 32 | FO10: 0 | FP10: 50 | FQ10: 0 | FR10: 0 | FS10: 0 | FT10: 0 | FU10: 0 | FV10: 0 | FW10: 0 | FX10: 0 | FY10: 0 | FZ10: 0 | GA10: 0 | GB10: 62 | GC10: 0 | GD10: 47 | GE10: 0 | GF10: 0 | GG10: 58 | GH10: 9 | GI10: 0 | GJ10: 80 | GK10: 0 | GL10: 0 | GM10: 158 | GN10: 43 | GO10: 0 | GP10: 58 | GQ10: 0 | GR10: 31
